<?xml version="1.0" ?>
<!-- =================================================================================== -->
<!-- |    This document was autogenerated by xacro from icub.xacro                     | -->
<!-- |    EDITING THIS FILE BY HAND IS NOT RECOMMENDED                                 | -->
<!-- =================================================================================== -->
<!-- icub URDF model -->
<robot name="icub" xmlns:xacro="http://ros.org/wiki/xacro">
  <link name="world"/>
  <joint name="reference" type="floating">
    <parent link="world"/>
    <child link="waist"/>
    <origin rpy="0 0 0" xyz="0 0 0"/>
  </joint>
  <!-- INDEX -->
  <!-- just press ctrl+f to search -->
  <!-- LINKS -->
  <!-- waist, chest, lap_belt_1, lap_belt_2, neck_yaw_link, neck_roll_link, head -->
  <!-- l_hip_pitch_link, l_hip_roll_link, l_hip_yaw_link, l_upper_leg, l_lower_leg, l_ankle_1, l_ankle_2, left_foot -->
  <!-- r_hip_pitch_link, r_hip_roll_link, r_hip_yaw_link, r_upper_leg, r_lower_leg, r_ankle_1, r_ankle_2, right_foot -->
  <!-- l_shoulder_pitch_link, l_shoulder_roll_link, l_shoulder_yaw_link, l_upper_arm, l_elbow_1, l_forearm, l_wrist_1, l_hand -->
  <!-- r_shoulder_pitch_link, r_shoulder_roll_link, r_shoulder_yaw_link, r_upper_arm, r_elbow_1, r_forearm, r_wrist_1, r_hand -->
  <!-- JOINTS -->
  <!-- torso_pitch, torso_roll, torso_yaw, neck_pitch, neck_roll, neck_yaw -->
  <!-- l_hip_pitch, l_hip_roll, l_leg_ft_sensor, l_hip_yaw, l_knee, l_ankle_pitch, l_ankle_roll, left_foot_joint -->
  <!-- r_hip_pitch, r_hip_roll, r_leg_ft_sensor, r_hip_yaw, r_knee, r_ankle_pitch, r_ankle_roll, right_foot_joint -->
  <!-- l_shoulder_pitch, l_shoulder_roll, l_shoulder_yaw, l_arm_ft_sensor, l_elbow_joint, l_wrist_prosup, l_wrist_pitch, l_wrist_yaw -->
  <!-- r_shoulder_pitch, r_shoulder_roll, r_shoulder_yaw, r_arm_ft_sensor, r_elbow_joint, r_wrist_prosup, r_wrist_pitch, r_wrist_yaw -->
  <link name="waist">
    <inertial>
      <origin rpy="0 0 0" xyz="-0.04 0 0.05"/>
      <mass value="5.09143"/>
      <inertia ixx="0.0139679" ixy="-0.0000593488" ixz="-0.000155458" iyy="0.0202112" iyz="-0.00170968" izz="0.0249124"/>
    </inertial>
    <collision name="waist_link_collision">
      <origin rpy="0 0 0" xyz="0 0 0.02"/>
      <geometry>
        <mesh filename="package://icub_description/meshes/collision/dae/icub_simple_collision_waist.dae"/>
      </geometry>
    </collision>
    <visual name="waist_link_visual">
      <origin rpy="0 0 0" xyz="0 0 0.02"/>
      <geometry>
        <mesh filename="package://icub_description/meshes/visual/dae/icub_waist.dae"/>
      </geometry>
    </visual>
  </link>
  <link name="l_hip_pitch_link">
    <inertial>
      <mass value="0.695"/>
      <origin rpy="0 0 0" xyz="0 -0.00691643 -0.0023047"/>
      <inertia ixx="0.01" ixy="0" ixz="0" iyy="0.01" iyz="0" izz="0.01"/>
    </inertial>
    <visual>
      <origin rpy="2.35619 1.5708 0.785398" xyz="0 0 0"/>
      <geometry>
        <mesh filename="package://icub_description/meshes/collision/dae/icub_simple_collision_l_hip_pitch_link.dae"/>
      </geometry>
    </visual>
    <collision>
      <origin rpy="2.35619 1.5708 0.785398" xyz="0 0 0"/>
      <geometry>
        <mesh filename="package://icub_description/meshes/visual/dae/icub_l_hip_pitch_link.dae"/>
      </geometry>
    </collision>
  </link>
  <link name="l_hip_roll_link">
    <inertial>
      <mass value="0.982"/>
      <origin rpy="0 0 0" xyz="0.0010964 0 0.0598624"/>
      <inertia ixx="0.0253646" ixy="0.0000012116" ixz="0.000491081" iyy="0.0272714" iyz="0.0000115713" izz="0.01"/>
    </inertial>
    <visual>
      <origin rpy="-2.35623 -1.5708 -0.785361" xyz="0 0 0"/>
      <geometry>
        <mesh filename="package://icub_description/meshes/collision/dae/icub_simple_collision_l_hip_roll_link.dae"/>
      </geometry>
      <material name="material.metal">
        <texture/>
        <color rgba="0 0 0 1"/>
      </material>
    </visual>
    <collision>
      <origin rpy="-2.35623 -1.5708 -0.785361" xyz="0 0 0"/>
      <geometry>
        <mesh filename="package://icub_description/meshes/visual/dae/icub_l_hip_roll_link.dae"/>
      </geometry>
    </collision>
  </link>
  <link name="l_hip_yaw_link">
    <inertial>
      <origin rpy="0 0 0" xyz="0 0 0"/>
      <mass value="0.1"/>
      <inertia ixx="0.01" ixy="0" ixz="0" iyy="0.01" iyz="0" izz="0.01"/>
    </inertial>
    <visual>
      <origin rpy="0 0 0" xyz="0 0 0"/>
      <geometry>
        <mesh filename="package://icub_description/meshes/collision/dae/icub_simple_collision_l_hip_yaw_link.dae"/>
      </geometry>
      <material name="material.metal">
        <texture/>
        <color rgba="0 0 0 1"/>
      </material>
    </visual>
    <collision>
      <origin rpy="0 0 0" xyz="0 0 0"/>
      <geometry>
        <mesh filename="package://icub_description/meshes/visual/dae/icub_l_hip_yaw_link.dae"/>
      </geometry>
    </collision>
  </link>
  <link name="l_upper_leg">
    <inertial>
      <origin rpy="0 0 0" xyz="0.0001504 -0.078827 0.0033485"/>
      <mass value="1.8084"/>
      <inertia ixx="0.00647124065718" ixy="-0.000117510769467" ixz="-0.0000357294757981" iyy="0.00144843621276" iyz="-0.000137708519804" izz="0.00646464360719"/>
    </inertial>
    <collision name="l_upper_leg_collision">
      <origin rpy="0 1.5708 1.5708" xyz="0 0 0"/>
      <geometry>
        <mesh filename="package://icub_description/meshes/collision/dae/icub_simple_collision_l_upper_leg.dae"/>
      </geometry>
    </collision>
    <visual name="l_upper_leg_visual">
      <origin rpy="0 1.5708 1.5708" xyz="0 0 0"/>
      <geometry>
        <mesh filename="package://icub_description/meshes/visual/dae/icub_l_upper_leg.dae"/>
      </geometry>
    </visual>
  </link>
  <link name="l_lower_leg">
    <inertial>
      <origin rpy="0 0 0" xyz="-0.09 0.0 0.000868"/>
      <mass value="1.4724"/>
      <inertia ixx="0.0154559" ixy="-0.0013903" ixz="-0.0039454" iyy="0.070277" iyz="0.00071995" izz="0.0659645"/>
    </inertial>
    <collision name="l_lower_leg_collision">
      <origin rpy="-3.14159 0 1.5708" xyz="0.010945 0.0009175 0"/>
      <geometry>
        <mesh filename="package://icub_description/meshes/collision/dae/icub_simple_collision_l_lower_leg.dae"/>
      </geometry>
    </collision>
    <visual name="l_lower_leg_visual">
      <origin rpy="-3.14159 0 1.5708" xyz="0.010945 0.0009175 0"/>
      <geometry>
        <mesh filename="package://icub_description/meshes/visual/dae/icub_l_lower_leg.dae"/>
      </geometry>
    </visual>
  </link>
  <link name="l_ankle_1">
    <inertial>
      <origin rpy="0 0 0" xyz="0.0000265892 -0.00082253 0.0102574"/>
      <mass value="0.6798"/>
      <inertia ixx="4.76593" ixy="0.0000097426" ixz="0.0000268085" iyy="0.01" iyz="-0.000353796" izz="0.01"/>
    </inertial>
    <collision name="l_ankle_1_collision">
      <origin rpy="1.5708 0 0" xyz="-0.001555 0 0.0009175"/>
      <geometry>
        <mesh filename="package://icub_description/meshes/collision/dae/icub_simple_collision_l_ankle_1.dae"/>
      </geometry>
    </collision>
    <visual name="l_ankle_1_visual">
      <origin rpy="1.5708 0 0" xyz="-0.001555 0 0.0009175"/>
      <geometry>
        <mesh filename="package://icub_description/meshes/visual/dae/icub_l_ankle_1.dae"/>
      </geometry>
    </visual>
  </link>
  <link name="l_ankle_2">
    <inertial>
      <origin rpy="0 0 0" xyz="-0.0035 0 0"/>
      <mass value="0.267485"/>
      <inertia ixx="0.01" ixy="0" ixz="0" iyy="0.01" iyz="0" izz="0.01"/>
    </inertial>
    <collision name="l_ankle_2_collision">
      <origin rpy="0 0 0" xyz="0 0 0"/>
      <geometry>
        <mesh filename="package://icub_description/meshes/collision/dae/icub_simple_collision_l_ankle_2.dae"/>
      </geometry>
    </collision>
    <visual name="l_ankle_2_visual">
      <origin rpy="0 0 0" xyz="0 0 0"/>
      <geometry>
        <mesh filename="package://icub_description/meshes/visual/dae/icub_l_ankle_2.dae"/>
      </geometry>
    </visual>
  </link>
  <link name="left_foot">
    <inertial>
      <!-- <origin xyz="0.0336906 -0.0053662 -0.001154" rpy="-1.57079632679 0 -1.57079632679"/> -->
      <origin xyz="0.0336906 -0.0053662 -0.001154"/>
      <mass value="0.382372"/>
      <inertia ixx="0.00121061" ixy="-0.00000365345" ixz="0.000578649" iyy="0.00141515" iyz="-0.0000767241" izz="0.000273665"/>
    </inertial>
    <collision name="l_foot_collision">
      <origin rpy="-1.5708 0 -1.5708" xyz="0.04 0 0.02"/>
      <!-- <origin rpy="-1.5708 0 -1.5708" xyz="0.04 0 0.01"/> -->
      <geometry>
        <!-- <mesh filename="package://icub_description/meshes/collision/dae/icub_simple_collision_l_foot.dae"/> -->
        <box size="0.09 0.035 0.2"/>
      </geometry>
    </collision>
    <visual name="l_foot_visual">
      <origin rpy="-1.5708 0 -1.5708" xyz="0.04 0 0.01"/>
      <geometry>
        <mesh filename="package://icub_description/meshes/visual/dae/icub_l_foot.dae"/>
      </geometry>
    </visual>
  </link>
  <link name="r_hip_pitch_link">
    <inertial>
      <mass value="0.695"/>
      <origin rpy="0 0 0" xyz="0 -0.00691643 0.0023047"/>
      <inertia ixx="0.01" ixy="-0.000022209" ixz="-0.0000139712" iyy="0.01" iyz="-0.0000477629" izz="0.01"/>
    </inertial>
    <visual>
      <origin rpy="-1.3734 -1.5708 -0.380506" xyz="0 0 0"/>
      <geometry>
        <mesh filename="package://icub_description/meshes/collision/dae/icub_simple_collision_r_hip_pitch_link.dae"/>
      </geometry>
    </visual>
    <collision>
      <origin rpy="-1.3734 -1.5708 -0.380506" xyz="0 0 0"/>
      <geometry>
        <mesh filename="package://icub_description/meshes/visual/dae/icub_r_hip_pitch_link.dae"/>
      </geometry>
    </collision>
  </link>
  <link name="r_hip_roll_link">
    <inertial>
      <mass value="0.982"/>
      <origin rpy="0 -0 0" xyz="0.0010964 -0.0000313229 0.0598624"/>
      <inertia ixx="0.0253646" ixy="0.0000012116" ixz="0.000491081" iyy="0.0272714" iyz="0.0000115713" izz="0.01"/>
    </inertial>
    <visual>
      <origin rpy="0.785327 -1.5708 -0.785327" xyz="0 0 0"/>
      <geometry>
        <mesh filename="package://icub_description/meshes/collision/dae/icub_simple_collision_r_hip_roll_link.dae"/>
      </geometry>
      <material name="material.metal">
        <texture/>
        <color rgba="0 0 0 1"/>
      </material>
    </visual>
    <collision>
      <origin rpy="0.785327 -1.5708 -0.785327" xyz="0 0 0"/>
      <geometry>
        <mesh filename="package://icub_description/meshes/visual/dae/icub_r_hip_roll_link.dae"/>
      </geometry>
    </collision>
  </link>
  <link name="r_hip_yaw_link">
    <inertial>
      <!-- <origin xyz="-0.000123 -0.0002823 0.008718" rpy="-1.57079632679 0 -1.57079632679"/> -->
      <origin xyz="-0.000123 -0.0002823 0.008718"/>
      <mass value="0.126212"/>
      <inertia ixx="0.000327938" ixy="0.00000267901" ixz="-0.0000000441463" iyy="0.000569957" iyz="0.000000332338" izz="0.000326449"/>
    </inertial>
    <visual>
      <origin rpy="0 0 0" xyz="0 0 0"/>
      <geometry>
        <mesh filename="package://icub_description/meshes/collision/dae/icub_simple_collision_r_hip_yaw_link.dae"/>
      </geometry>
      <material name="material.metal">
        <texture/>
        <color rgba="0 0 0 1"/>
      </material>
    </visual>
    <collision>
      <origin rpy="0 0 0" xyz="0 0 0"/>
      <geometry>
        <mesh filename="package://icub_description/meshes/visual/dae/icub_r_hip_yaw_link.dae"/>
      </geometry>
    </collision>
  </link>
  <link name="r_upper_leg">
    <inertial>
      <origin rpy="0 0 0" xyz="0 -0.078866 0.0033612"/>
      <mass value="1.8035"/>
      <inertia ixx="0.00646378343182" ixy="0.000122685853522" ixz="0.0000494531545868" iyy="0.00144539832219" iyz="-0.000137533175718" izz="0.00645582688618"/>
    </inertial>
    <collision name="r_upper_leg_collision">
      <origin rpy="0 -1.5708 1.5708" xyz="0 0 0"/>
      <geometry>
        <mesh filename="package://icub_description/meshes/collision/dae/icub_simple_collision_r_upper_leg.dae"/>
      </geometry>
    </collision>
    <visual name="r_upper_leg_visual">
      <origin rpy="0 -1.5708 1.5708" xyz="0 0 0"/>
      <geometry>
        <mesh filename="package://icub_description/meshes/visual/dae/icub_r_upper_leg.dae"/>
      </geometry>
    </visual>
  </link>
  <link name="r_lower_leg">
    <inertial>
      <origin rpy="0 0 0" xyz="-0.09 0 0.0011052"/>
      <mass value="1.472"/>
      <inertia ixx="0.0154559" ixy="-0.0013903" ixz="0.0039454" iyy="0.070277" iyz="-0.00071995" izz="0.0659645"/>
    </inertial>
    <collision name="r_lower_leg_collision">
      <origin rpy="3.14159 0 1.5708" xyz="0.010945 0.0009175 0"/>
      <geometry>
        <mesh filename="package://icub_description/meshes/collision/dae/icub_simple_collision_r_lower_leg.dae"/>
      </geometry>
    </collision>
    <visual name="r_lower_leg_visual">
      <origin rpy="3.14159 0 1.5708" xyz="0.010945 0.0009175 0"/>
      <geometry>
        <mesh filename="package://icub_description/meshes/visual/dae/icub_r_lower_leg.dae"/>
      </geometry>
    </visual>
  </link>
  <link name="r_ankle_1">
    <inertial>
      <origin rpy="0 0 0" xyz="-0.0000265892 -0.00082253 -0.0102574"/>
      <mass value="0.6803"/>
      <inertia ixx="4.76593" ixy="0.0000097426" ixz="-0.0000268085" iyy="0.01" iyz="0.000353796" izz="0.01"/>
    </inertial>
    <collision name="r_ankle_1_collision">
      <origin rpy="-1.5708 0 0" xyz="-0.001555 0 -0.0009175"/>
      <geometry>
        <mesh filename="package://icub_description/meshes/collision/dae/icub_simple_collision_r_ankle_1.dae"/>
      </geometry>
    </collision>
    <visual name="r_ankle_1_visual">
      <origin rpy="-1.5708 0 0" xyz="-0.001555 0 -0.0009175"/>
      <geometry>
        <mesh filename="package://icub_description/meshes/visual/dae/icub_r_ankle_1.dae"/>
      </geometry>
    </visual>
  </link>
  <link name="r_ankle_2">
    <inertial>
      <origin rpy="0 0 0" xyz="-0.0035 0 0"/>
      <mass value="0.267485"/>
      <inertia ixx="0.01" ixy="0" ixz="0" iyy="0.01" iyz="0" izz="0.01"/>
    </inertial>
    <collision name="r_ankle_2_collision">
      <origin rpy="0 0 0" xyz="0 0 0"/>
      <geometry>
        <mesh filename="package://icub_description/meshes/collision/dae/icub_simple_collision_r_ankle_2.dae"/>
      </geometry>
    </collision>
    <visual name="r_ankle_2_visual">
      <origin rpy="0 0 0" xyz="0 0 0"/>
      <geometry>
        <mesh filename="package://icub_description/meshes/visual/dae/icub_r_ankle_2.dae"/>
      </geometry>
    </visual>
  </link>
  <link name="right_foot">
    <inertial>
      <!-- <origin xyz="0.0336237 0.0053646 -0.001138" rpy="-1.5708 0 -1.5708"/> -->
      <!-- <origin xyz="0.0336237 0.0053646 -0.001138"/> -->
      <origin xyz="0.0336906 0.0053662 -0.001154"/>
      <mass value="0.38227"/>
      <inertia ixx="0.00120765" ixy="0.00000370545" ixz="-0.000578137" iyy="0.00141242" iyz="-0.00000782502" izz="0.000273419"/>
    </inertial>
    <collision name="r_foot_collision">
      <!-- <origin rpy="-1.5708 0 -1.5708" xyz="0.04 0 0.01"/> -->
      <origin rpy="-1.5708 0 -1.5708" xyz="0.04 0 0.02"/>
      <geometry>
        <!-- <mesh filename="package://icub_description/meshes/collision/dae/icub_simple_collision_r_foot.dae"/> -->
        <box size="0.09 0.035 0.2"/>
      </geometry>
    </collision>
    <visual name="r_foot_visual">
      <origin rpy="-1.5708 0 -1.5708" xyz="0.04 0 0.01"/>
      <geometry>
        <mesh filename="package://icub_description/meshes/visual/dae/icub_r_foot.dae"/>
      </geometry>
    </visual>
  </link>
  <link name="chest">
    <inertial>
      <mass value="4.81"/>
      <origin rpy="0 0 0" xyz="-0.07 0.12 0"/>
      <inertia ixx="0.07472" ixy="-0.000036" ixz="-0.00004705" iyy="0.08145" iyz="0.004567" izz="0.01306"/>
    </inertial>
    <collision name="chest_collision">
      <origin rpy="0 -1.5708 1.5708" xyz="-0.0055 0 0"/>
      <geometry>
        <mesh filename="package://icub_description/meshes/collision/dae/icub_simple_collision_chest.dae"/>
      </geometry>
    </collision>
    <visual name="chest_visual">
      <origin rpy="0 -1.5708 1.5708" xyz="-0.0055 0 0"/>
      <geometry>
        <mesh filename="package://icub_description/meshes/visual/dae/icub_chest.dae"/>
      </geometry>
    </visual>
  </link>
  <link name="lap_belt_1">
    <inertial>
      <origin rpy="0 0 0" xyz="0.0270921359 0 -0.0004398"/>
      <mass value="0.67144"/>
      <inertia ixx="0.00040911" ixy="-0.00000104522" ixz="-0.00000102516" iyy="0.000384141" iyz="0.00000650708" izz="0.000299445"/>
    </inertial>
    <collision name="lap_belt_1_collision">
      <origin rpy="-1.5708 0 0" xyz="0 0 0"/>
      <geometry>
        <mesh filename="package://icub_description/meshes/collision/dae/icub_simple_collision_lap_belt_1.dae"/>
      </geometry>
    </collision>
    <visual name="lap_belt_1_visual">
      <origin rpy="-1.5708 0 -1.5708" xyz="0 0 0"/>
      <geometry>
        <mesh filename="package://icub_description/meshes/visual/dae/icub_lap_belt_1.dae"/>
      </geometry>
    </visual>
  </link>
  <link name="lap_belt_2">
    <inertial>
      <origin rpy="0 0 0" xyz="0 0 0"/>
      <mass value="0.425685"/>
      <inertia ixx="0.000829234" ixy="0.0000000237006" ixz="0.0000000925231" iyy="0.000436517" iyz="-0.000000174814" izz="0.000604802"/>
    </inertial>
    <visual>
      <origin rpy="0 0 0" xyz="0 0 0"/>
      <geometry>
        <mesh filename="package://icub_description/meshes/collision/dae/icub_simple_collision_lap_belt_2.dae"/>
      </geometry>
      <material name="material.metal">
        <texture/>
        <color rgba="0 0 0 1"/>
      </material>
    </visual>
    <collision>
      <origin rpy="0 0 0" xyz="0 0 0"/>
      <geometry>
        <mesh filename="package://icub_description/meshes/visual/dae/icub_lap_belt_2.dae"/>
      </geometry>
    </collision>
  </link>
  <link name="neck_yaw_link">
    <inertial>
      <mass value="0.272306"/>
      <origin rpy="0 0 0" xyz="0 0.00337529 0.00545442"/>
      <inertia ixx="0.000142823" ixy="-0.0000000592615" ixz="-0.0000000220067" iyy="0.0000828849" iyz="-0.0000913211" izz="0.000876203"/>
    </inertial>
    <collision name="neck_ayw_collision">
      <origin rpy="0 -1.5708 -1.5708" xyz="0 0 -0.0055"/>
      <geometry>
        <mesh filename="package://icub_description/meshes/collision/dae/icub_simple_collision_neck_yaw_link.dae"/>
      </geometry>
    </collision>
    <visual name="neck_yaw_visual">
      <origin rpy="0 -1.5708 -1.5708" xyz="0 0 -0.0055"/>
      <geometry>
        <mesh filename="package://icub_description/meshes/visual/dae/icub_neck_yaw_link.dae"/>
      </geometry>
    </visual>
  </link>
  <link name="neck_roll_link">
    <inertial>
      <origin rpy="0 0 0" xyz="0.0143705608 0.006567 -0.0063842"/>
      <mass value="0.125793"/>
      <inertia ixx="0.000040647" ixy="0.0000000809156" ixz="-0.0000000374998" iyy="0.00003881" iyz="0.00000939717" izz="0.000047535"/>
    </inertial>
    <collision name="neck_roll_collision">
      <origin rpy="0 -1.5708 1.5708" xyz="0 0.0055 0.0235"/>
      <geometry>
        <mesh filename="package://icub_description/meshes/collision/dae/icub_simple_collision_neck_roll_link.dae"/>
      </geometry>
    </collision>
    <visual name="neck_roll_visual">
      <origin rpy="0 -1.5708 1.5708" xyz="0 0.0055 0.0235"/>
      <geometry>
        <mesh filename="package://icub_description/meshes/visual/dae/icub_neck_roll_link.dae"/>
      </geometry>
    </visual>
  </link>
  <link name="head">
    <inertial>
      <origin rpy="0 0 0" xyz="0.02 -0.113511 0"/>
      <mass value="1.50691"/>
      <inertia ixx="0.00680478" ixy="-0.0000160267" ixz="0.0000728166" iyy="0.00634736" iyz="0.000292091" izz="0.00478116"/>
    </inertial>
    <collision name="head_collision">
      <origin rpy="0 1.5708 -1.5708" xyz="0.0045 -0.0235 0"/>
      <geometry>
        <mesh filename="package://icub_description/meshes/collision/dae/icub_simple_collision_head.dae"/>
      </geometry>
    </collision>
    <visual name="head_visual">
      <origin rpy="0 1.5708 -1.5708" xyz="0.0045 -0.0235 0"/>
      <geometry>
        <mesh filename="package://icub_description/meshes/visual/dae/icub_head.dae"/>
      </geometry>
    </visual>
  </link>
  <link name="l_shoulder_pitch_link">
    <inertial>
      <mass value="0.189"/>
      <origin rpy="0 0 0" xyz="0 0.0187 -0.00119"/>
      <inertia ixx="0.01" ixy="9e-09" ixz="0" iyy="0.01" iyz="-0.000000017" izz="0.01"/>
    </inertial>
    <collision name="l_shoulder_pitch_collision">
      <origin rpy="0 1.5708 -1.5708" xyz="0 0.109285 -0.00521101"/>
      <geometry>
        <mesh filename="package://icub_description/meshes/collision/dae/icub_simple_collision_l_shoulder_pitch_link.dae"/>
      </geometry>
    </collision>
    <visual name="l_shoulder_pitch_visual">
      <origin rpy="0 1.5708 -1.5708" xyz="0 0.109285 -0.00521101"/>
      <geometry>
        <mesh filename="package://icub_description/meshes/visual/dae/icub_l_shoulder_pitch_link.dae"/>
      </geometry>
    </visual>
  </link>
  <link name="l_shoulder_roll_link">
    <inertial>
      <mass value="0.179"/>
      <origin rpy="0 0 0" xyz="0 -0.00627 0.0166"/>
      <inertia ixx="0.01" ixy="0.000000466" ixz="0.000000365" iyy="0.01" iyz="-0.000020524" izz="0.01"/>
    </inertial>
    <collision name="l_shoulder_roll_collision">
      <origin rpy="1.00126 1.5708 2.57206" xyz="-0.00154529 -0.00521101 0"/>
      <geometry>
        <mesh filename="package://icub_description/meshes/collision/dae/icub_simple_collision_l_shoulder_roll_link.dae"/>
      </geometry>
    </collision>
    <visual name="l_shoulder_roll_visual">
      <origin rpy="1.00126 1.5708 2.57206" xyz="-0.00154529 -0.00521101 0"/>
      <geometry>
        <mesh filename="package://icub_description/meshes/visual/dae/icub_l_shoulder_roll_link.dae"/>
      </geometry>
    </visual>
  </link>
  <link name="l_shoulder_yaw_link">
    <inertial>
      <mass value="0.156157"/>
      <origin rpy="0 0 0" xyz="0 0 0"/>
      <inertia ixx="0.01" ixy="-0.00000005662" ixz="-0.0000043618" iyy="0.01" iyz="-0.000000742844" izz="0.01"/>
    </inertial>
    <visual>
      <origin rpy="0 0 0" xyz="0 0 0"/>
      <geometry>
        <mesh filename="package://icub_description/meshes/collision/dae/icub_simple_collision_l_shoulder_yaw_link.dae"/>
      </geometry>
      <material name="material.metal">
        <texture/>
        <color rgba="0 0 0 1"/>
      </material>
    </visual>
    <collision>
      <origin rpy="0 0 0" xyz="0 0 0"/>
      <geometry>
        <mesh filename="package://icub_description/meshes/visual/dae/icub_l_shoulder_yaw_link.dae"/>
      </geometry>
    </collision>
  </link>
  <link name="l_upper_arm">
    <inertial>
      <mass value="0.727843"/>
      <origin rpy="0 0 0" xyz="-0.03 -0.0000987 0.0298"/>
      <inertia ixx="0.01" ixy="-0.00000108" ixz="-0.00000229" iyy="0.01" iyz="0.00000357" izz="0.01"/>
    </inertial>
    <collision name="l_upper_arm_collision">
      <origin rpy="0 0 -1.309" xyz="-0.0204334 0.000143922 -0.068"/>
      <geometry>
        <mesh filename="package://icub_description/meshes/collision/dae/icub_simple_collision_l_upper_arm.dae"/>
      </geometry>
    </collision>
    <visual name="l_upper_arm_visual">
      <origin rpy="0 0 -1.309" xyz="-0.0204334 0.000143922 -0.068"/>
      <geometry>
        <mesh filename="package://icub_description/meshes/visual/dae/icub_l_upper_arm.dae"/>
      </geometry>
    </visual>
  </link>
  <link name="l_elbow_1">
    <inertial>
      <mass value="0.074"/>
      <origin rpy="0 0 0" xyz="-0.03 0.00371 -0.00105"/>
      <inertia ixx="0.01" ixy="-0.000000515" ixz="-0.000000408" iyy="0.01" iyz="-3.71e-07" izz="0.01"/>
    </inertial>
    <collision name="l_elbow_1_collision">
      <origin rpy="1.5708 0 0" xyz="-0.02 0 0"/>
      <geometry>
        <mesh filename="package://icub_description/meshes/collision/dae/icub_simple_collision_l_elbow_1.dae"/>
      </geometry>
    </collision>
    <visual name="l_elbow_1_visual">
      <origin rpy="1.5708 0 0" xyz="-0.02 0 0"/>
      <geometry>
        <mesh filename="package://icub_description/meshes/visual/dae/icub_l_elbow_1.dae"/>
      </geometry>
    </visual>
  </link>
  <link name="l_forearm">
    <inertial>
      <mass value="0.525"/>
      <origin rpy="0 0 0" xyz="0.000347 0.066 0.00476"/>
      <inertia ixx="0.000765393" ixy="0.000004337" ixz="0.000000239" iyy="0.000164578" iyz="0.000019381" izz="0.00069806"/>
    </inertial>
    <collision name="l_forearm_collision">
      <origin rpy="1.39994 1.5708 2.97073" xyz="-0.000143922 0 0.0204334"/>
      <geometry>
        <mesh filename="package://icub_description/meshes/collision/dae/icub_simple_collision_l_forearm.dae"/>
      </geometry>
    </collision>
    <visual name="l_forearm_visual">
      <origin rpy="1.39994 1.5708 2.97073" xyz="-0.000143922 0 0.0204334"/>
      <geometry>
        <mesh filename="package://icub_description/meshes/visual/dae/icub_l_forearm.dae"/>
      </geometry>
    </visual>
  </link>
  <link name="l_wrist_1">
    <inertial>
      <mass value="0.1"/>
      <origin rpy="0 0 0" xyz="0 0 0"/>
      <inertia ixx="0.1" ixy="0" ixz="0" iyy="0.1" iyz="0" izz="0.1"/>
    </inertial>
    <collision name="l_wrist_1_collision">
      <origin rpy="0 0 0" xyz="0 0 0"/>
      <geometry>
        <mesh filename="package://icub_description/meshes/collision/dae/icub_simple_collision_l_wrist_1.dae"/>
      </geometry>
    </collision>
    <visual name="l_wrist_1_visual">
      <origin rpy="0 0 0" xyz="0 0 0"/>
      <geometry>
        <mesh filename="package://icub_description/meshes/visual/dae/icub_l_wrist_1.dae"/>
      </geometry>
    </visual>
  </link>
  <link name="l_hand">
    <inertial>
      <mass value="0.113"/>
      <origin rpy="0 0 0" xyz="0.03523 0 0"/>
      <inertia ixx="0.1" ixy="0" ixz="0" iyy="0.1" iyz="0" izz="0.1"/>
    </inertial>
    <visual>
      <origin rpy="0 0 0" xyz="0 0.0204334 -0.000143922"/>
      <geometry>
        <mesh filename="package://icub_description/meshes/visual/dae/icub_l_hand.dae" scale="1 1 1"/>
      </geometry>
      <material name="material.metal">
        <texture/>
        <color rgba="0 0 0 1"/>
      </material>
    </visual>
    <collision>
      <origin rpy="0 0 0" xyz="0 0.0204334 -0.000143922"/>
      <geometry>
        <mesh filename="package://icub_description/meshes/collision/dae/icub_simple_collision_l_hand.dae" scale="1 1 1"/>
      </geometry>
    </collision>
  </link>
  <link name="r_shoulder_pitch_link">
    <inertial>
      <mass value="0.189"/>
      <origin rpy="0 -0 0" xyz="0 0.0187 0.00119"/>
      <inertia ixx="0.01" ixy="0" ixz="0" iyy="0.01" iyz="0" izz="0.01"/>
    </inertial>
    <collision name="r_shoulder_pitch_collision">
      <origin rpy="-0.0815582 1.5708 1.48924" xyz="0 0.109285 0.00521101"/>
      <geometry>
        <mesh filename="package://icub_description/meshes/collision/dae/icub_simple_collision_r_shoulder_pitch_link.dae"/>
      </geometry>
    </collision>
    <visual name="r_shoulder_pitch_visual">
      <origin rpy="-0.0815582 1.5708 1.48924" xyz="0 0.109285 0.00521101"/>
      <geometry>
        <mesh filename="package://icub_description/meshes/visual/dae/icub_r_shoulder_pitch_link.dae"/>
      </geometry>
    </visual>
  </link>
  <link name="r_shoulder_roll_link">
    <inertial>
      <mass value="0.179"/>
      <origin rpy="0 0 0" xyz="0 -0.00627 -0.0166"/>
      <inertia ixx="0.01" ixy="0.0" ixz="0.0" iyy="0.01" iyz="0.0" izz="0.01"/>
    </inertial>
    <collision name="r_shoulder_roll_collision">
      <origin rpy="2.14034 -1.5708 -0.56954" xyz="-0.00154529 -0.00521101 0"/>
      <geometry>
        <mesh filename="package://icub_description/meshes/collision/dae/icub_simple_collision_r_shoulder_roll_link.dae"/>
      </geometry>
    </collision>
    <visual name="r_shoulder_roll_visual">
      <origin rpy="2.14034 -1.5708 -0.56954" xyz="-0.00154529 -0.00521101 0"/>
      <geometry>
        <mesh filename="package://icub_description/meshes/visual/dae/icub_r_shoulder_roll_link.dae"/>
      </geometry>
    </visual>
  </link>
  <link name="r_shoulder_yaw_link">
    <inertial>
      <mass value="0.155"/>
      <origin rpy="0 0 0" xyz="0.0 0 0.0"/>
      <inertia ixx="0.01" ixy="0.0" ixz="0.0" iyy="0.01" iyz="0.0" izz="0.01"/>
    </inertial>
    <visual>
      <origin rpy="0 0 0" xyz="0 0 0"/>
      <geometry>
        <mesh filename="package://icub_description/meshes/collision/dae/icub_simple_collision_r_shoulder_yaw_link.dae"/>
      </geometry>
      <material name="material.metal">
        <texture/>
        <color rgba="0 0 0 1"/>
      </material>
    </visual>
    <collision>
      <origin rpy="0 0 0" xyz="0 0 0"/>
      <geometry>
        <mesh filename="package://icub_description/meshes/visual/dae/icub_r_shoulder_yaw_link.dae"/>
      </geometry>
    </collision>
  </link>
  <link name="r_upper_arm">
    <inertial>
      <mass value="0.729"/>
      <origin rpy="0 -0 0" xyz="-0.03 0 0.0298828"/>
      <inertia ixx="0.000408" ixy="-0.00000108" ixz="-0.00000229" iyy="0.00038" iyz="0.00000357" izz="0.00026"/>
    </inertial>
    <collision name="r_upper_arm_collision">
      <origin rpy="-3.14159 0 1.309" xyz="-0.0204334 -0.000143922 -0.068"/>
      <geometry>
        <mesh filename="package://icub_description/meshes/collision/dae/icub_simple_collision_r_upper_arm.dae"/>
      </geometry>
    </collision>
    <visual name="r_upper_arm_visual">
      <origin rpy="-3.14159 0 1.309" xyz="-0.0204334 -0.000143922 -0.068"/>
      <geometry>
        <mesh filename="package://icub_description/meshes/visual/dae/icub_r_upper_arm.dae"/>
      </geometry>
    </visual>
  </link>
  <link name="r_elbow_1">
    <inertial>
      <mass value="0.074"/>
      <origin rpy="0 0 0" xyz="0.03 -0.00371 0.00105"/>
      <inertia ixx="0.01" ixy="0.0" ixz="0.0" iyy="0.01" iyz="0.0" izz="0.01"/>
    </inertial>
    <collision name="r_elbow_1_collision">
      <origin rpy="1.5708 0 0" xyz="0.02 0 0"/>
      <geometry>
        <mesh filename="package://icub_description/meshes/collision/dae/icub_simple_collision_r_elbow_1.dae"/>
      </geometry>
    </collision>
    <visual name="r_elbow_1_visual">
      <origin rpy="1.5708 0 0" xyz="0.02 0 0"/>
      <geometry>
        <mesh filename="package://icub_description/meshes/visual/dae/icub_r_elbow_1.dae"/>
      </geometry>
    </visual>
  </link>
  <link name="r_forearm">
    <inertial>
      <mass value="0.525"/>
      <origin rpy="0 0 0" xyz="-0.000347 -0.066 -0.00476"/>
      <inertia ixx="0.000766" ixy="0.00000566" ixz="0.0000014" iyy="0.000164" iyz="0.0000182" izz="0.000699"/>
    </inertial>
    <collision name="r_forearm_collision">
      <origin rpy="0 1.5708 1.5708" xyz="0.000143922 0 -0.0204334"/>
      <geometry>
        <mesh filename="package://icub_description/meshes/collision/dae/icub_simple_collision_r_forearm.dae"/>
      </geometry>
    </collision>
    <visual name="r_forearm_visual">
      <origin rpy="0 1.5708 1.5708" xyz="0.000143922 0 -0.0204334"/>
      <geometry>
        <mesh filename="package://icub_description/meshes/visual/dae/icub_r_forearm.dae"/>
      </geometry>
    </visual>
  </link>
  <link name="r_wrist_1">
    <inertial>
      <mass value="0.1"/>
      <origin rpy="0 0 0" xyz="0 0 0"/>
      <inertia ixx="0.1" ixy="0" ixz="0" iyy="0.1" iyz="0" izz="0.1"/>
    </inertial>
    <collision name="r_wrist_1_collision">
      <origin rpy="0 0 0" xyz="0 0 0"/>
      <geometry>
        <mesh filename="package://icub_description/meshes/collision/dae/icub_simple_collision_r_wrist_1.dae"/>
      </geometry>
    </collision>
    <visual name="r_wrist_1_visual">
      <origin rpy="0 0 0" xyz="0 0 0"/>
      <geometry>
        <mesh filename="package://icub_description/meshes/visual/dae/icub_r_wrist_1.dae"/>
      </geometry>
    </visual>
  </link>
  <link name="r_hand">
    <inertial>
      <mass value="0.113"/>
      <origin rpy="0 -0 0" xyz="0.03523 0.0 0.007"/>
      <inertia ixx="0.1" ixy="0.0" ixz="0.0" iyy="0.1" iyz="0.0" izz="0.1"/>
    </inertial>
    <visual>
      <origin rpy="0 0 -3.14159" xyz="0 0.0204334 0.000143922"/>
      <geometry>
        <mesh filename="package://icub_description/meshes/visual/dae/icub_r_hand.dae" scale="1 1 1"/>
      </geometry>
      <material name="material.metal">
        <texture/>
        <color rgba="0 0 0 1"/>
      </material>
    </visual>
    <collision>
      <origin rpy="0 0 -3.14159" xyz="0 0.0204334 0.000143922"/>
      <geometry>
        <mesh filename="package://icub_description/meshes/collision/dae/icub_simple_collision_r_hand.dae" scale="1 1 1"/>
      </geometry>
    </collision>
  </link>
  <!-- Joints -->
  <joint name="torso_pitch" type="revolute">
    <origin rpy="0 -1.5708 0" xyz="0 0 0.09"/>
    <child link="lap_belt_1"/>
    <parent link="waist"/>
    <axis use_parent_model_frame="1" xyz="0 1 0"/>
    <limit effort="36" lower="-0.383972" upper="1.46608" velocity="8"/>
    <dynamics damping="1" friction="0" spring_reference="0" spring_stiffness="0"/>
  </joint>
  <joint name="torso_roll" type="revolute">
    <origin rpy="1.5708 0 -1.5708" xyz="0.032 0 0"/>
    <child link="lap_belt_2"/>
    <parent link="lap_belt_1"/>
    <axis use_parent_model_frame="1" xyz="0 1 0"/>
    <limit effort="80" lower="-0.680678" upper="0.680678" velocity="8"/>
    <dynamics damping="1" friction="0" spring_reference="0" spring_stiffness="0"/>
  </joint>
  <joint name="torso_yaw" type="revolute">
    <origin rpy="-1.5708 0 -1.5708" xyz="0 -0.0055 0"/>
    <child link="chest"/>
    <parent link="lap_belt_2"/>
    <axis use_parent_model_frame="1" xyz="0 -1 0"/>
    <limit effort="80" lower="-1.02974" upper="1.02974" velocity="8"/>
    <dynamics damping="1" friction="0" spring_reference="0" spring_stiffness="0"/>
  </joint>
  <joint name="neck_pitch" type="revolute">
    <origin rpy="1.5708 0 1.5708" xyz="0.00231 0.1933 0"/>
    <child link="neck_yaw_link"/>
    <parent link="chest"/>
    <axis use_parent_model_frame="1" xyz="0 1 0"/>
    <limit effort="20" lower="-0.698132" upper="0.523599" velocity="8"/>
    <dynamics damping="1" friction="0" spring_reference="0" spring_stiffness="0"/>
  </joint>
  <joint name="neck_roll" type="revolute">
    <origin rpy="-1.5708 0 -1.5708" xyz="0.0095 0 0"/>
    <child link="neck_roll_link"/>
    <parent link="neck_yaw_link"/>
    <axis use_parent_model_frame="1" xyz="0 -1 0"/>
    <limit effort="20" lower="-0.349065850399" upper="0.349065850399" velocity="8"/>
    <dynamics damping="1" friction="0" spring_reference="0" spring_stiffness="0"/>
  </joint>
  <joint name="neck_yaw" type="revolute">
    <origin rpy="-1.5708 0 1.5708" xyz="0 0 0"/>
    <child link="head"/>
    <parent link="neck_roll_link"/>
    <axis use_parent_model_frame="1" xyz="0 -1 0"/>
    <limit effort="20" lower="-0.959931" upper="0.959931" velocity="8"/>
    <dynamics damping="1" friction="0" spring_reference="0" spring_stiffness="0"/>
  </joint>
  <joint name="l_hip_pitch" type="revolute">
    <origin rpy="-3.14159 1.5708 3.1415" xyz="0 0.0681 0"/>
    <axis xyz="0 -1 0"/>
    <parent link="waist"/>
    <child link="l_hip_pitch_link"/>
    <dynamics damping="1" friction="0"/>
    <limit effort="84" lower="-0.767945" upper="2.30383" velocity="5.1"/>
  </joint>
  <joint name="l_hip_roll" type="revolute">
    <origin rpy="3.14159 -1.5708 0" xyz="0 0 0"/>
    <axis xyz="1 0 0"/>
    <parent link="l_hip_pitch_link"/>
    <child link="l_hip_roll_link"/>
    <dynamics damping="1" friction="0"/>
    <limit effort="84" lower="0.0" upper="1.57079632679" velocity="7.64"/>
  </joint>
  <joint name="l_hip_yaw" type="revolute">
    <origin rpy="-1.5708 0 0" xyz="0 0 -0.0665"/>
    <axis xyz="0 1 0"/>
    <parent link="l_hip_yaw_link"/>
    <child link="l_upper_leg"/>
    <dynamics damping="1" friction="0"/>
    <limit effort="40" lower="-1.37881" upper="1.37881" velocity="7.64"/>
  </joint>
  <joint name="l_knee" type="revolute">
    <origin rpy="3.14159 0 1.5708" xyz="-0.0009175 -0.234545 0"/>
    <child link="l_lower_leg"/>
    <parent link="l_upper_leg"/>
    <axis use_parent_model_frame="1" xyz="0 0 -1"/>
    <limit effort="30" lower="-2.18166" upper="0" velocity="7.64"/>
    <dynamics damping="1" friction="0" spring_reference="0" spring_stiffness="0"/>
  </joint>
  <joint name="l_ankle_pitch" type="revolute">
    <origin rpy="-1.5708 0 0" xyz="-0.2005 0 0"/>
    <child link="l_ankle_1"/>
    <parent link="l_lower_leg"/>
    <axis use_parent_model_frame="1" xyz="0 -1 0"/>
    <limit effort="24" lower="-0.733038" upper="0.366519" velocity="7.64"/>
    <dynamics damping="1" friction="0" spring_reference="0" spring_stiffness="0"/>
  </joint>
  <joint name="l_ankle_roll" type="revolute">
    <origin rpy="0 -1.5708 0" xyz="0 0 0"/>
    <child link="l_ankle_2"/>
    <parent link="l_ankle_1"/>
    <axis use_parent_model_frame="1" xyz="1 0 0"/>
    <limit effort="11" lower="-0.418879" upper="0.418879" velocity="7.64"/>
    <dynamics damping="1" friction="0" spring_reference="0" spring_stiffness="0"/>
  </joint>
  <joint name="r_hip_pitch" type="revolute">
    <origin rpy="0 1.5708 3.1415" xyz="0 -0.0681 0"/>
    <axis xyz="0 1 0"/>
    <parent link="waist"/>
    <child link="r_hip_pitch_link"/>
    <dynamics damping="1" friction="0"/>
    <limit effort="84" lower="-0.767945" upper="2.30383" velocity="5.1"/>
  </joint>
  <joint name="r_hip_roll" type="revolute">
    <origin rpy="0 1.5708 0" xyz="0 0 0"/>
    <axis xyz="-1 0 0"/>
    <parent link="r_hip_pitch_link"/>
    <child link="r_hip_roll_link"/>
    <dynamics damping="1" friction="0"/>
    <limit effort="84" lower="0.0" upper="1.57079632679" velocity="7.64"/>
  </joint>
  <joint name="r_hip_yaw" type="revolute">
    <origin rpy="-1.5708 0 0" xyz="0 0 -0.0665"/>
    <axis xyz="0 -1 0"/>
    <parent link="r_hip_yaw_link"/>
    <child link="r_upper_leg"/>
    <dynamics damping="1" friction="0"/>
    <limit effort="40" lower="-1.37881" upper="1.37881" velocity="7.64"/>
  </joint>
  <joint name="r_knee" type="revolute">
    <origin rpy="3.14159 0 1.5708" xyz="-0.0009175 -0.234545 0"/>
    <child link="r_lower_leg"/>
    <parent link="r_upper_leg"/>
    <axis use_parent_model_frame="1" xyz="0 0 -1"/>
    <limit effort="30" lower="-2.18166" upper="0" velocity="7.64"/>
    <dynamics damping="1" friction="0" spring_reference="0" spring_stiffness="0"/>
  </joint>
  <joint name="r_ankle_pitch" type="revolute">
    <origin rpy="1.5708 -0 0" xyz="-0.2005 0 0"/>
    <child link="r_ankle_1"/>
    <parent link="r_lower_leg"/>
    <axis use_parent_model_frame="1" xyz="0 1 0"/>
    <limit effort="24" lower="-0.733038" upper="0.366519" velocity="7.64"/>
    <dynamics damping="1" friction="0" spring_reference="0" spring_stiffness="0"/>
  </joint>
  <joint name="r_ankle_roll" type="revolute">
    <origin rpy="0 1.5708 3.14159" xyz="0 0 0"/>
    <child link="r_ankle_2"/>
    <parent link="r_ankle_1"/>
    <axis use_parent_model_frame="1" xyz="-1 0 0"/>
    <limit effort="11" lower="-0.418879" upper="0.418879" velocity="7.64"/>
    <dynamics damping="1" friction="0" spring_reference="0" spring_stiffness="0"/>
  </joint>
  <joint name="l_shoulder_pitch" type="revolute">
    <origin rpy="1.309 0 1.5708" xyz="0.00525 0.1433 -0.11026"/>
    <child link="l_shoulder_pitch_link"/>
    <parent link="chest"/>
    <axis use_parent_model_frame="1" xyz="0 -1 0"/>
    <limit effort="84" lower="-1.65806" upper="0.0872665" velocity="8"/>
    <dynamics damping="1" friction="0" spring_reference="0" spring_stiffness="0"/>
  </joint>
  <joint name="l_shoulder_roll" type="revolute">
    <origin rpy="1.5708 0 -1.5708" xyz="0 0 0"/>
    <child link="l_shoulder_roll_link"/>
    <parent link="l_shoulder_pitch_link"/>
    <axis use_parent_model_frame="1" xyz="0 1 0"/>
    <limit effort="84" lower="0" upper="2.80649" velocity="8"/>
    <dynamics damping="1" friction="0" spring_reference="0" spring_stiffness="0"/>
  </joint>
  <joint name="l_shoulder_yaw" type="revolute">
    <origin rpy="0 0 1.309" xyz="0 0 0"/>
    <child link="l_shoulder_yaw_link"/>
    <parent link="l_shoulder_roll_link"/>
    <axis use_parent_model_frame="1" xyz="0 0 1"/>
    <limit effort="34" lower="-0.645772" upper="1.74533" velocity="8"/>
    <dynamics damping="1" friction="0" spring_reference="0" spring_stiffness="0"/>
  </joint>
  <joint name="l_elbow_joint" type="revolute">
    <origin rpy="0 0 0" xyz="0 0 0.08428"/>
    <child link="l_elbow_1"/>
    <parent link="l_upper_arm"/>
    <axis use_parent_model_frame="1" xyz="0 1 0"/>
    <limit effort="40" lower="0.0959931" upper="1.85005" velocity="8"/>
    <dynamics damping="1" friction="0" spring_reference="0" spring_stiffness="0"/>
  </joint>
  <joint name="l_wrist_prosup" type="revolute">
    <origin rpy="1.5708 0 -1.5708" xyz="-0.015 0 0"/>
    <child link="l_forearm"/>
    <parent link="l_elbow_1"/>
    <axis use_parent_model_frame="1" xyz="0 1 0"/>
    <limit effort="0.45" lower="-0.872665" upper="0.872665" velocity="8"/>
    <dynamics damping="1" friction="0" spring_reference="0" spring_stiffness="0"/>
  </joint>
  <joint name="r_shoulder_pitch" type="revolute">
    <origin rpy="-1.309 0 1.5708" xyz="0.00525 0.1433 0.11026"/>
    <child link="r_shoulder_pitch_link"/>
    <parent link="chest"/>
    <axis use_parent_model_frame="1" xyz="0 1 0"/>
    <limit effort="84" lower="-1.65806" upper="0.0872665" velocity="8"/>
    <dynamics damping="1" friction="0" spring_reference="0" spring_stiffness="0"/>
  </joint>
  <joint name="r_shoulder_roll" type="revolute">
    <origin rpy="-1.5708 0 -1.5708" xyz="0 0 0"/>
    <child link="r_shoulder_roll_link"/>
    <parent link="r_shoulder_pitch_link"/>
    <axis use_parent_model_frame="1" xyz="0 -1 0"/>
    <limit effort="84" lower="0" upper="2.80649" velocity="8"/>
    <dynamics damping="1" friction="0" spring_reference="0" spring_stiffness="0"/>
  </joint>
  <joint name="r_shoulder_yaw" type="revolute">
    <origin rpy="3.14159 0 1.309" xyz="0 0 0"/>
    <child link="r_shoulder_yaw_link"/>
    <parent link="r_shoulder_roll_link"/>
    <axis use_parent_model_frame="1" xyz="0 0 -1"/>
    <limit effort="34" lower="-0.645772" upper="1.74533" velocity="8"/>
    <dynamics damping="1" friction="0" spring_reference="0" spring_stiffness="0"/>
  </joint>
  <joint name="r_elbow_joint" type="revolute">
    <origin rpy="3.14159 0 3.14159" xyz="0 0 0.08428"/>
    <child link="r_elbow_1"/>
    <parent link="r_upper_arm"/>
    <axis use_parent_model_frame="1" xyz="0 1 0"/>
    <limit effort="40" lower="0.0959931" upper="1.85005" velocity="8"/>
    <dynamics damping="1" friction="0" spring_reference="0" spring_stiffness="0"/>
  </joint>
  <joint name="r_wrist_prosup" type="revolute">
    <origin rpy="1.5708 0 -1.5708" xyz="0.015 0 0"/>
    <child link="r_forearm"/>
    <parent link="r_elbow_1"/>
    <axis use_parent_model_frame="1" xyz="0 1 0"/>
    <limit effort="0.45" lower="-0.872665" upper="0.872665" velocity="8"/>
    <dynamics damping="1" friction="0" spring_reference="0" spring_stiffness="0"/>
  </joint>
  <joint name="l_wrist_pitch" type="revolute">
    <origin rpy="1.5708 0 1.5708" xyz="0 0.1373 0"/>
    <child link="l_wrist_1"/>
    <parent link="l_forearm"/>
    <axis use_parent_model_frame="1" xyz="0 1 0"/>
    <limit effort="0.65" lower="-1.13446" upper="0" velocity="8"/>
    <dynamics damping="1" friction="0" spring_reference="0" spring_stiffness="0"/>
  </joint>
  <joint name="r_wrist_pitch" type="revolute">
    <origin rpy="1.5708 0 1.5708" xyz="0 -0.1373 0"/>
    <child link="r_wrist_1"/>
    <parent link="r_forearm"/>
    <axis use_parent_model_frame="1" xyz="0 1 0"/>
    <limit effort="0.65" lower="-1.13446" upper="0" velocity="8"/>
    <dynamics damping="1" friction="0" spring_reference="0" spring_stiffness="0"/>
  </joint>
  <joint name="l_wrist_yaw" type="revolute">
    <origin rpy="0 0 0" xyz="0 0 0"/>
    <axis xyz="0 0 1"/>
    <parent link="l_wrist_1"/>
    <child link="l_hand"/>
    <dynamics damping="1" friction="0"/>
    <limit effort="0.65" lower="-0.436332" upper="0.436332" velocity="8"/>
  </joint>
  <joint name="r_wrist_yaw" type="revolute">
    <origin rpy="0 0 3.14159" xyz="0 0 0"/>
    <axis xyz="0 0 1"/>
    <parent link="r_wrist_1"/>
    <child link="r_hand"/>
    <dynamics damping="1" friction="0"/>
    <limit effort="0.65" lower="-0.436332" upper="0.436332" velocity="8"/>
  </joint>
  <joint name="r_leg_ft_sensor" type="fixed">
    <origin rpy="0 0 0" xyz="0 0 0.0665"/>
    <child link="r_hip_yaw_link"/>
    <parent link="r_hip_roll_link"/>
    <axis use_parent_model_frame="1" xyz="0 0 0"/>
    <dynamics damping="0" friction="0" spring_reference="0" spring_stiffness="0"/>
  </joint>
  <gazebo reference="r_hip_yaw">
    <sensor name="right_leg_ft" type="force_torque">
      <always_on>1</always_on>
      <update_rate>100</update_rate>
      <pose>0 0 0 0 0 0</pose>
      <plugin filename="libgazebo_yarp_forcetorque.so" name="right_leg_ft_plugin">
        <yarpConfigurationFile>model://icub_description/conf/FT/gazebo_icub_right_leg_ft.ini</yarpConfigurationFile>
      </plugin>
    </sensor>
  </gazebo>
  <joint name="l_leg_ft_sensor" type="fixed">
    <origin rpy="0 0 0" xyz="0 0 0.0665"/>
    <child link="l_hip_yaw_link"/>
    <parent link="l_hip_roll_link"/>
    <axis use_parent_model_frame="1" xyz="0 0 0"/>
    <dynamics damping="0" friction="0" spring_reference="0" spring_stiffness="0"/>
  </joint>
  <gazebo reference="l_hip_yaw">
    <sensor name="left_leg_ft" type="force_torque">
      <always_on>1</always_on>
      <update_rate>100</update_rate>
      <plugin filename="libgazebo_yarp_forcetorque.so" name="left_leg_ft_plugin">
        <yarpConfigurationFile>model://icub_description/conf/FT/gazebo_icub_left_leg_ft.ini</yarpConfigurationFile>
      </plugin>
    </sensor>
  </gazebo>
  <joint name="r_arm_ft_sensor" type="fixed">
    <origin rpy="0 0 0" xyz="0.015 0 0.068"/>
    <child link="r_upper_arm"/>
    <parent link="r_shoulder_yaw_link"/>
    <axis use_parent_model_frame="1" xyz="-0 0 0"/>
    <limit effort="0" lower="0" upper="0" velocity="0"/>
    <dynamics damping="0" friction="0" spring_reference="0" spring_stiffness="0"/>
  </joint>
  <gazebo reference="r_shoulder_yaw">
    <sensor name="right_arm_ft" type="force_torque">
      <always_on>1</always_on>
      <update_rate>100</update_rate>
      <plugin filename="libgazebo_yarp_forcetorque.so" name="right_arm_ft_plugin">
        <yarpConfigurationFile>model://icub_description/conf/FT/gazebo_icub_right_arm_ft.ini</yarpConfigurationFile>
      </plugin>
    </sensor>
  </gazebo>
  <joint name="l_arm_ft_sensor" type="fixed">
    <origin rpy="0 0 0" xyz="0.015 0 0.068"/>
    <child link="l_upper_arm"/>
    <parent link="l_shoulder_yaw_link"/>
    <axis use_parent_model_frame="1" xyz="-0 0 0"/>
    <dynamics damping="0" friction="0" spring_reference="0" spring_stiffness="0"/>
  </joint>
  <gazebo reference="l_shoulder_yaw">
    <sensor name="left_arm_ft" type="force_torque">
      <always_on>1</always_on>
      <update_rate>100</update_rate>
      <plugin filename="libgazebo_yarp_forcetorque.so" name="left_arm_ft_plugin">
        <yarpConfigurationFile>model://icub_description/conf/FT/gazebo_icub_left_arm_ft.ini</yarpConfigurationFile>
      </plugin>
    </sensor>
  </gazebo>
  <joint name="r_foot_ft_sensor" type="fixed">
    <origin rpy="0 0 0" xyz="-0.0035 0 0"/>
    <child link="right_foot"/>
    <parent link="r_ankle_2"/>
    <axis use_parent_model_frame="1" xyz="0 0 0"/>
    <dynamics damping="0" friction="0" spring_reference="0" spring_stiffness="0"/>
  </joint>
  <gazebo reference="r_ankle_roll">
    <sensor name="right_foot_ft" type="force_torque">
      <always_on>1</always_on>
      <update_rate>100</update_rate>
      <pose>0 0 0 3.14 0 0</pose>
      <visualize>false</visualize>
      <force_torque>
        <measure_direction>child_to_parent</measure_direction>
        <frame>sensor</frame>
      </force_torque>
      <plugin filename="libgazebo_yarp_forcetorque.so" name="right_foot_ft_plugin">
        <yarpConfigurationFile>model://icub_description/conf/FT/gazebo_icub_right_foot_ft.ini</yarpConfigurationFile>
      </plugin>
    </sensor>
  </gazebo>
  <joint name="l_foot_ft_sensor" type="fixed">
    <origin rpy="0 0 0" xyz="-0.0035 0 0"/>
    <child link="left_foot"/>
    <parent link="l_ankle_2"/>
    <axis use_parent_model_frame="1" xyz="0 0 0"/>
    <dynamics damping="0" friction="0" spring_reference="0" spring_stiffness="0"/>
  </joint>
  <gazebo reference="l_ankle_roll">
    <sensor name="left_foot_ft" type="force_torque">
      <always_on>1</always_on>
      <update_rate>100</update_rate>
      <pose>0 0 0 -3.14 0 0</pose>
      <visualize>false</visualize>
      <force_torque>
        <measure_direction>child_to_parent</measure_direction>
        <frame>sensor</frame>
      </force_torque>
      <plugin filename="libgazebo_yarp_forcetorque.so" name="left_foot_ft_plugin">
        <yarpConfigurationFile>model://icub_description/conf/FT/gazebo_icub_left_foot_ft.ini</yarpConfigurationFile>
      </plugin>
    </sensor>
  </gazebo>
  <gazebo reference="r_foot_ft_sensor">
    <disableFixedJointLumping>true</disableFixedJointLumping>
    <preserveFixedJoint>true</preserveFixedJoint>
  </gazebo>
  <gazebo reference="l_foot_ft_sensor">
    <disableFixedJointLumping>true</disableFixedJointLumping>
    <preserveFixedJoint>true</preserveFixedJoint>
  </gazebo>
  <gazebo reference="left_foot">
    <collision name="l_foot_collision">
      <max_contacts>10</max_contacts>
      <surface>
        <contact>
          <ode>
            <soft_erp>0.2</soft_erp>
            <soft_cfm>0</soft_cfm>
            <kp>18000000</kp>
            <kd>100</kd>
            <max_vel>100</max_vel>
            <min_depth>0.0001</min_depth>
          </ode>
        </contact>
        <friction>
          <ode>
            <mu>0.998000</mu>
            <mu2>0.998000</mu2>
            <fdir1>1 0 0</fdir1>
          </ode>
        </friction>
        <bounce>
          <restitution_coefficient>0</restitution_coefficient>
          <threshold>100000</threshold>
        </bounce>
      </surface>
    </collision>
  </gazebo>
  <gazebo reference="right_foot">
    <collision name="r_foot_collision">
      <max_contacts>10</max_contacts>
      <surface>
        <contact>
          <ode>
            <soft_erp>0.2</soft_erp>
            <soft_cfm>0</soft_cfm>
            <kp>18000000</kp>
            <kd>100</kd>
            <max_vel>100</max_vel>
            <min_depth>0.0001</min_depth>
          </ode>
        </contact>
        <friction>
          <ode>
            <mu>0.998000</mu>
            <mu2>0.998000</mu2>
            <fdir1>1 0 0</fdir1>
          </ode>
        </friction>
        <bounce>
          <restitution_coefficient>0</restitution_coefficient>
          <threshold>100000</threshold>
        </bounce>
      </surface>
    </collision>
  </gazebo>
  <gazebo reference="r_leg_ft_sensor">
    <sensor name="right_leg_ft" type="force_torque">
      <always_on>1</always_on>
      <update_rate>100</update_rate>
      <pose>0 0 0 0 0 0</pose>
      <plugin filename="libgazebo_yarp_forcetorque.so" name="right_leg_ft_plugin">
        <yarpConfigurationFile>model://icub_description/conf/FT/gazebo_icub_right_leg_ft.ini</yarpConfigurationFile>
      </plugin>
    </sensor>
  </gazebo>
  <gazebo reference="l_leg_ft_sensor">
    <sensor name="left_leg_ft" type="force_torque">
      <always_on>1</always_on>
      <update_rate>100</update_rate>
      <plugin filename="libgazebo_yarp_forcetorque.so" name="left_leg_ft_plugin">
        <yarpConfigurationFile>model://icub_description/conf/FT/gazebo_icub_left_leg_ft.ini</yarpConfigurationFile>
      </plugin>
    </sensor>
  </gazebo>
  <gazebo reference="r_arm_ft_sensor">
    <sensor name="right_arm_ft" type="force_torque">
      <always_on>1</always_on>
      <update_rate>100</update_rate>
      <plugin filename="libgazebo_yarp_forcetorque.so" name="right_arm_ft_plugin">
        <yarpConfigurationFile>model://icub_description/conf/FT/gazebo_icub_right_arm_ft.ini</yarpConfigurationFile>
      </plugin>
    </sensor>
  </gazebo>
  <gazebo reference="l_arm_ft_sensor">
    <sensor name="left_arm_ft" type="force_torque">
      <always_on>1</always_on>
      <update_rate>100</update_rate>
      <plugin filename="libgazebo_yarp_forcetorque.so" name="left_arm_ft_plugin">
        <yarpConfigurationFile>model://icub_description/conf/FT/gazebo_icub_left_arm_ft.ini</yarpConfigurationFile>
      </plugin>
    </sensor>
  </gazebo>
  <gazebo reference="r_foot_ft_sensor">
    <sensor name="right_foot_ft" type="force_torque">
      <always_on>1</always_on>
      <update_rate>100</update_rate>
      <pose>0 0 0 3.14 0 0</pose>
      <visualize>false</visualize>
      <force_torque>
        <measure_direction>child_to_parent</measure_direction>
        <frame>sensor</frame>
      </force_torque>
      <plugin filename="libgazebo_yarp_forcetorque.so" name="right_foot_ft_plugin">
        <yarpConfigurationFile>model://icub_description/conf/FT/gazebo_icub_right_foot_ft.ini</yarpConfigurationFile>
      </plugin>
    </sensor>
  </gazebo>
  <gazebo reference="l_foot_ft_sensor">
    <sensor name="left_foot_ft" type="force_torque">
      <always_on>1</always_on>
      <update_rate>100</update_rate>
      <pose>0 0 0 -3.14 0 0</pose>
      <visualize>false</visualize>
      <force_torque>
        <measure_direction>child_to_parent</measure_direction>
        <frame>sensor</frame>
      </force_torque>
      <plugin filename="libgazebo_yarp_forcetorque.so" name="left_foot_ft_plugin">
        <yarpConfigurationFile>model://icub_description/conf/FT/gazebo_icub_left_foot_ft.ini</yarpConfigurationFile>
      </plugin>
    </sensor>
  </gazebo>
  <gazebo reference="head">
    <sensor name="imu_sensor" type="imu">
      <always_on>1</always_on>
      <update_rate>100</update_rate>
      <visualize>1</visualize>
      <imu/>
      <plugin filename="libgazebo_yarp_imu.so" name="iCub_yarp_gazebo_plugin_IMU">
        <yarpConfigurationFile>model://icub_description/conf/gazebo_icub_inertial.ini</yarpConfigurationFile>
      </plugin>
      <pose>0.0185 -0.1108 0.0066 1.5708 -0 0</pose>
    </sensor>
  </gazebo>
  <gazebo>
    <plugin filename="libgazebo_yarp_controlboard.so" name="controlboard_torso">
      <yarpConfigurationFile>model://icub_description/conf/gazebo_icub_torso.ini</yarpConfigurationFile>
      <initialConfiguration>0.0 0.0 0.436</initialConfiguration>
    </plugin>
  </gazebo>
  <gazebo>
    <plugin filename="libgazebo_yarp_controlboard.so" name="controlboard_head">
      <yarpConfigurationFile>model://icub_description/conf/gazebo_icub_head_no_eyes.ini</yarpConfigurationFile>
      <initialConfiguration>0.174 0.0 0.0</initialConfiguration>
    </plugin>
  </gazebo>
  <gazebo>
    <plugin filename="libgazebo_yarp_controlboard.so" name="controlboard_left_arm_no_arm">
      <yarpConfigurationFile>model://icub_description/conf/gazebo_icub_left_arm_no_hand_for_no_hand_model.ini</yarpConfigurationFile>
      <initialConfiguration>-0.1 0.35 0.174 0.7 0.0 -0.3 0.0</initialConfiguration>
    </plugin>
  </gazebo>
  <gazebo>
    <plugin filename="libgazebo_yarp_controlboard.so" name="controlboard_right_arm_no_arm">
      <yarpConfigurationFile>model://icub_description/conf/gazebo_icub_right_arm_no_hand_for_no_hand_model.ini</yarpConfigurationFile>
      <initialConfiguration>-0.1 0.35 0.174 0.7 0.0 -0.3 0.0</initialConfiguration>
    </plugin>
  </gazebo>
  <gazebo>
    <plugin filename="libgazebo_yarp_controlboard.so" name="controlboard_left_leg">
      <yarpConfigurationFile>model://icub_description/conf/gazebo_icub_left_leg.ini</yarpConfigurationFile>
      <initialConfiguration>0.35 0.174 0.174 -0.698 -0.35 -0.1103125</initialConfiguration>
    </plugin>
  </gazebo>
  <gazebo>
    <plugin filename="libgazebo_yarp_controlboard.so" name="controlboard_right_leg">
      <yarpConfigurationFile>model://icub_description/conf/gazebo_icub_right_leg.ini</yarpConfigurationFile>
      <initialConfiguration>0.35 0.174 0.174 -0.698 -0.35 -0.1103125</initialConfiguration>
    </plugin>
  </gazebo>
  <gazebo>
    <plugin filename="libgazebo_yarp_externalwrench.so" name="apply_external_wrench">
      <robotNamefromConfigFile>model://icub_description/conf/gazebo_icub_robotname.ini</robotNamefromConfigFile>
    </plugin>
  </gazebo>
  <gazebo>
    <plugin filename="libmc_gazebo.so" name="mc_gazebo">
      <robotName>icub_description</robotName>
      <baseName>waist</baseName>
    </plugin>
  </gazebo>
  <gazebo>
    <plugin filename="libRobotDbg.so" name="RobotDbg">
    </plugin>
  </gazebo>
<!-- foot contact points -->
  <link name="fl_left_foot">
   <inertial>
     <origin xyz="0 0 0"/>
     <mass value="0.000001"/>
     <inertia ixx="1" ixy="0" ixz="0" iyy="1" iyz="0" izz="1"/>
   </inertial>
  </link>
  <joint name="fl_left_foot_contact" type="fixed">
     <origin rpy="0 0 0 " xyz="0.14 -0.045 0.01525"/>
     <child link="fl_left_foot"/>
     <parent link="left_foot"/>
     <axis use_parent_model_frame="1" xyz="0 0 0"/>
     <limit effort="10000" lower="0" upper="0" velocity="0"/>
     <dynamics damping="0" friction="0" spring_reference="0" spring_stiffness="0"/>
  </joint>

  <link name="fr_left_foot">
   <inertial>
     <origin xyz="0 0 0"/>
     <mass value="0.000001"/>
     <inertia ixx="1" ixy="0" ixz="0" iyy="1" iyz="0" izz="1"/>
   </inertial>
  </link>
  <joint name="fr_left_foot_contact" type="fixed">
     <origin rpy="0 0 0 " xyz="0.14 0.045 0.01525"/>
     <child link="fr_left_foot"/>
     <parent link="left_foot"/>
     <axis use_parent_model_frame="1" xyz="0 0 0"/>
     <limit effort="10000" lower="0" upper="0" velocity="0"/>
     <dynamics damping="0" friction="0" spring_reference="0" spring_stiffness="0"/>
  </joint>

  <link name="bl_left_foot">
    <inertial>
      <origin xyz="0 0 0"/>
      <mass value="0.000001"/>
      <inertia ixx="0.000001" ixy="0.000001" ixz="0.000001" iyy="0.000001" iyz="0.000001" izz="0.000001"/>
    </inertial>
  </link>
  <joint name="bl_left_foot_contact" type="fixed">
    <origin rpy="0 0 0 " xyz="-0.06 -0.045 0.01525"/>
    <child link="bl_left_foot"/>
    <parent link="left_foot"/>
    <axis use_parent_model_frame="1" xyz="0 0 0"/>
    <dynamics damping="0" friction="0" spring_reference="0" spring_stiffness="0"/>
  </joint>

  <link name="br_left_foot">
    <inertial>
      <origin xyz="0 0 0"/>
      <mass value="0.000001"/>
      <inertia ixx="0.000001" ixy="0.000001" ixz="0.000001" iyy="0.000001" iyz="0.000001" izz="0.000001"/>
    </inertial>
  </link>
  <joint name="br_left_foot_contact" type="fixed">
    <origin rpy="0 0 0 " xyz="-0.06 0.045 0.01525"/>
    <child link="br_left_foot"/>
    <parent link="left_foot"/>
    <axis use_parent_model_frame="1" xyz="0 0 0"/>
    <dynamics damping="0" friction="0" spring_reference="0" spring_stiffness="0"/>
  </joint>

  <link name="fl_right_foot">
    <inertial>
      <origin xyz="0 0 0"/>
      <mass value="0.000001"/>
      <inertia ixx="0.000001" ixy="0.000001" ixz="0.000001" iyy="0.000001" iyz="0.000001" izz="0.000001"/>
    </inertial>
  </link>
  <joint name="fl_right_foot_contact" type="fixed">
   <origin rpy="0 0 0 " xyz="0.14 -0.045 0.01525"/>
   <child link="fl_right_foot"/>
   <parent link="right_foot"/>
   <axis use_parent_model_frame="1" xyz="0 0 0"/>
   <dynamics damping="0" friction="0" spring_reference="0" spring_stiffness="0"/>
  </joint>

  <link name="fr_right_foot">
    <inertial>
      <origin xyz="0 0 0"/>
      <mass value="0.000001"/>
      <inertia ixx="0.000001" ixy="0.000001" ixz="0.000001" iyy="0.000001" iyz="0.000001" izz="0.000001"/>
    </inertial>
  </link>
  <joint name="fr_right_foot_contact" type="fixed">
   <origin rpy="0 0 0 " xyz="0.14 0.045 0.01525"/>
   <child link="fr_right_foot"/>
   <parent link="right_foot"/>
   <axis use_parent_model_frame="1" xyz="0 0 0"/>
   <dynamics damping="0" friction="0" spring_reference="0" spring_stiffness="0"/>
 </joint>

 <link name="bl_right_foot">
   <inertial>
     <origin xyz="0 0 0"/>
     <mass value="0.000001"/>
     <inertia ixx="0.000001" ixy="0.000001" ixz="0.000001" iyy="0.000001" iyz="0.000001" izz="0.000001"/>
   </inertial>
 </link>
 <joint name="bl_right_foot_contact" type="fixed">
   <origin rpy="0 0 0 " xyz="-0.06 -0.045 0.01525"/>
   <child link="bl_right_foot"/>
   <parent link="right_foot"/>
   <axis use_parent_model_frame="1" xyz="0 0 0"/>
   <dynamics damping="0" friction="0" spring_reference="0" spring_stiffness="0"/>
 </joint>

   <link name="br_right_foot">
     <inertial>
       <origin xyz="0 0 0"/>
       <mass value="0.000001"/>
       <inertia ixx="0.000001" ixy="0.000001" ixz="0.000001" iyy="0.000001" iyz="0.000001" izz="0.000001"/>
     </inertial>
   </link>
   <joint name="br_right_foot_contact" type="fixed">
     <origin rpy="0 0 0 " xyz="-0.06 0.045 0.01525"/>
     <child link="br_right_foot"/>
     <parent link="right_foot"/>
     <axis use_parent_model_frame="1" xyz="0 0 0"/>
     <dynamics damping="0" friction="0" spring_reference="0" spring_stiffness="0"/>
   </joint>
</robot>