<?xml version="1.0" encoding="utf-8"?>
<!-- =================================================================================== -->
<!-- |    This document was autogenerated by xacro from ur3e_with_schunk_hand.xacro    | -->
<!-- |    EDITING THIS FILE BY HAND IS NOT RECOMMENDED                                 | -->
<!-- =================================================================================== -->
<robot name="ur3e_with_schunk_hand">
  <!--
    Base UR robot series xacro macro.

    NOTE: this is NOT a URDF. It cannot directly be loaded by consumers
    expecting a flattened '.urdf' file. See the top-level '.xacro' for that
    (but note: that .xacro must still be processed by the xacro command).

    For use in '.launch' files: use one of the 'load_urX.launch' convenience
    launch files.

    This file models the base kinematic chain of a UR robot, which then gets
    parameterised by various configuration files to convert it into a UR3(e),
    UR5(e), UR10(e) or UR16e.

    NOTE: the default kinematic parameters (ie: link lengths, frame locations,
    offets, etc) do not correspond to any particular robot. They are defaults
    only. There WILL be non-zero offsets between the Forward Kinematics results
    in TF (ie: robot_state_publisher) and the values reported by the Teach
    Pendant.

    For accurate (and robot-specific) transforms, the 'kinematics_parameters_file'
    parameter MUST point to a .yaml file containing the appropriate values for
    the targetted robot.

    If using the UniversalRobots/Universal_Robots_ROS_Driver, follow the steps
    described in the readme of that repository to extract the kinematic
    calibration from the controller and generate the required .yaml file.

    Main author of the migration to yaml configs: Ludovic Delval.

    Contributors to previous versions (in no particular order):

     - Felix Messmer
     - Kelsey Hawkins
     - Wim Meeussen
     - Shaun Edwards
     - Nadia Hammoudeh Garcia
     - Dave Hershberger
     - G. vd. Hoorn
     - Philip Long
     - Dave Coleman
     - Miguel Prada
     - Mathias Luedtke
     - Marcel Schnirring
     - Felix von Drigalski
     - Felix Exner
     - Jimmy Da Silva
     - Ajit Krisshna N L
     - Muhammad Asif Rana
  -->
  <!--
    NOTE: the macro defined in this file is NOT part of the public API of this
          package. Users CANNOT rely on this file being available, or stored in
          this location. Nor can they rely on the existence of the macro.
  -->
  <!-- links: main serial chain -->
  <link name="base_link"/>
  <link name="base_link_inertia">
    <visual>
      <origin rpy="0 0 3.14159265359" xyz="0 0 0"/>
      <geometry>
        <mesh filename="package://ur3e_description/meshes/ur3e/visual/base.dae"/>
      </geometry>
      <material name="LightGrey">
        <color rgba="0.7 0.7 0.7 1.0"/>
      </material>
    </visual>
    <collision>
      <origin rpy="0 0 3.14159265359" xyz="0 0 0"/>
      <geometry>
        <mesh filename="package://ur3e_description/meshes/ur3e/collision/base.stl"/>
      </geometry>
    </collision>
    <inertial>
      <mass value="2.0"/>
      <origin rpy="0 0 0" xyz="0 0 0"/>
      <inertia ixx="0.0030531654454" ixy="0.0" ixz="0.0" iyy="0.0030531654454" iyz="0.0" izz="0.005625"/>
    </inertial>
  </link>
  <link name="shoulder_link">
    <visual>
      <origin rpy="0 0 3.14159265359" xyz="0 0 0"/>
      <geometry>
        <mesh filename="package://ur3e_description/meshes/ur3e/visual/shoulder.dae"/>
      </geometry>
      <material name="LightGrey">
        <color rgba="0.7 0.7 0.7 1.0"/>
      </material>
    </visual>
    <collision>
      <origin rpy="0 0 3.14159265359" xyz="0 0 0"/>
      <geometry>
        <mesh filename="package://ur3e_description/meshes/ur3e/collision/shoulder.stl"/>
      </geometry>
    </collision>
    <inertial>
      <mass value="2.0"/>
      <origin rpy="0 0 0" xyz="0 0 0"/>
      <inertia ixx="0.0080931634294" ixy="0.0" ixz="0.0" iyy="0.0080931634294" iyz="0.0" izz="0.005625"/>
    </inertial>
  </link>
  <link name="upper_arm_link">
    <visual>
      <origin rpy="1.57079632679 0 -1.57079632679" xyz="0 0 0.12"/>
      <geometry>
        <mesh filename="package://ur3e_description/meshes/ur3e/visual/upperarm.dae"/>
      </geometry>
      <material name="LightGrey">
        <color rgba="0.7 0.7 0.7 1.0"/>
      </material>
    </visual>
    <collision>
      <origin rpy="1.57079632679 0 -1.57079632679" xyz="0 0 0.12"/>
      <geometry>
        <mesh filename="package://ur3e_description/meshes/ur3e/collision/upperarm.stl"/>
      </geometry>
    </collision>
    <inertial>
      <mass value="3.42"/>
      <origin rpy="0 1.57079632679 0" xyz="-0.121825 0.0 0.12"/>
      <inertia ixx="0.0217284832211" ixy="0.0" ixz="0.0" iyy="0.0217284832211" iyz="0.0" izz="0.00961875"/>
    </inertial>
  </link>
  <link name="forearm_link">
    <visual>
      <origin rpy="1.57079632679 0 -1.57079632679" xyz="0 0 0.027"/>
      <geometry>
        <mesh filename="package://ur3e_description/meshes/ur3e/visual/forearm.dae"/>
      </geometry>
      <material name="LightGrey">
        <color rgba="0.7 0.7 0.7 1.0"/>
      </material>
    </visual>
    <collision>
      <origin rpy="1.57079632679 0 -1.57079632679" xyz="0 0 0.027"/>
      <geometry>
        <mesh filename="package://ur3e_description/meshes/ur3e/collision/forearm.stl"/>
      </geometry>
    </collision>
    <inertial>
      <mass value="1.26"/>
      <origin rpy="0 1.57079632679 0" xyz="-0.1066 0.0 0.027"/>
      <inertia ixx="0.00654456758217" ixy="0.0" ixz="0.0" iyy="0.00654456758217" iyz="0.0" izz="0.00354375"/>
    </inertial>
  </link>
  <link name="wrist_1_link">
    <visual>
      <!-- TODO: Move this to a parameter -->
      <origin rpy="1.57079632679 0 0" xyz="0 0 -0.104"/>
      <geometry>
        <mesh filename="package://ur3e_description/meshes/ur3e/visual/wrist1.dae"/>
      </geometry>
      <material name="LightGrey">
        <color rgba="0.7 0.7 0.7 1.0"/>
      </material>
    </visual>
    <collision>
      <origin rpy="1.57079632679 0 0" xyz="0 0 -0.104"/>
      <geometry>
        <mesh filename="package://ur3e_description/meshes/ur3e/collision/wrist1.stl"/>
      </geometry>
    </collision>
    <inertial>
      <mass value="0.8"/>
      <origin rpy="0 0 0" xyz="0 0 0"/>
      <inertia ixx="0.002084999166" ixy="0.0" ixz="0.0" iyy="0.002084999166" iyz="0.0" izz="0.00225"/>
    </inertial>
  </link>
  <link name="wrist_2_link">
    <visual>
      <origin rpy="0 0 0" xyz="0 0 -0.08535"/>
      <geometry>
        <mesh filename="package://ur3e_description/meshes/ur3e/visual/wrist2.dae"/>
      </geometry>
      <material name="LightGrey">
        <color rgba="0.7 0.7 0.7 1.0"/>
      </material>
    </visual>
    <collision>
      <origin rpy="0 0 0" xyz="0 0 -0.08535"/>
      <geometry>
        <mesh filename="package://ur3e_description/meshes/ur3e/collision/wrist2.stl"/>
      </geometry>
    </collision>
    <inertial>
      <mass value="0.8"/>
      <origin rpy="0 0 0" xyz="0 0 0"/>
      <inertia ixx="0.002084999166" ixy="0.0" ixz="0.0" iyy="0.002084999166" iyz="0.0" izz="0.00225"/>
    </inertial>
  </link>
  <link name="wrist_3_link">
    <visual>
      <origin rpy="1.57079632679 0 0" xyz="0 0 -0.0921"/>
      <geometry>
        <mesh filename="package://ur3e_description/meshes/ur3e/visual/wrist3.dae"/>
      </geometry>
      <material name="LightGrey">
        <color rgba="0.7 0.7 0.7 1.0"/>
      </material>
    </visual>
    <collision>
      <origin rpy="1.57079632679 0 0" xyz="0 0 -0.0921"/>
      <geometry>
        <mesh filename="package://ur3e_description/meshes/ur3e/collision/wrist3.stl"/>
      </geometry>
    </collision>
    <inertial>
      <mass value="0.35"/>
      <origin rpy="0 0 0" xyz="0.0 0.0 -0.02"/>
      <inertia ixx="0.00013626661216" ixy="0.0" ixz="0.0" iyy="0.00013626661216" iyz="0.0" izz="0.0001792"/>
    </inertial>
  </link>
  <!-- joints: main serial chain -->
  <joint name="base_link-base_link_inertia" type="fixed">
    <parent link="base_link"/>
    <child link="base_link_inertia"/>
    <!-- 'base_link' is REP-103 aligned (so X+ forward), while the internal
           frames of the robot/controller have X+ pointing backwards.
           Use the joint between 'base_link' and 'base_link_inertia' (a dummy
           link/frame) to introduce the necessary rotation over Z (of pi rad).
      -->
    <origin rpy="0 0 3.14159265359" xyz="0 0 0"/>
  </joint>
  <joint name="shoulder_pan_joint" type="revolute">
    <parent link="base_link_inertia"/>
    <child link="shoulder_link"/>
    <origin rpy="0 0 0" xyz="0 0 0.15185"/>
    <axis xyz="0 0 1"/>
    <limit effort="56.0" lower="-6.28318530718" upper="6.28318530718" velocity="3.14159265359"/>
    <dynamics damping="0" friction="0"/>
  </joint>
  <joint name="shoulder_lift_joint" type="revolute">
    <parent link="shoulder_link"/>
    <child link="upper_arm_link"/>
    <origin rpy="1.570796327 0 0" xyz="0 0 0"/>
    <axis xyz="0 0 1"/>
    <limit effort="56.0" lower="-6.28318530718" upper="6.28318530718" velocity="3.14159265359"/>
    <dynamics damping="0" friction="0"/>
  </joint>
  <joint name="elbow_joint" type="revolute">
    <parent link="upper_arm_link"/>
    <child link="forearm_link"/>
    <origin rpy="0 0 0" xyz="-0.24355 0 0"/>
    <axis xyz="0 0 1"/>
    <limit effort="28.0" lower="-3.14159265359" upper="3.14159265359" velocity="3.14159265359"/>
    <dynamics damping="0" friction="0"/>
  </joint>
  <joint name="wrist_1_joint" type="revolute">
    <parent link="forearm_link"/>
    <child link="wrist_1_link"/>
    <origin rpy="0 0 0" xyz="-0.2132 0 0.13105"/>
    <axis xyz="0 0 1"/>
    <limit effort="12.0" lower="-6.28318530718" upper="6.28318530718" velocity="6.28318530718"/>
    <dynamics damping="0" friction="0"/>
  </joint>
  <joint name="wrist_2_joint" type="revolute">
    <parent link="wrist_1_link"/>
    <child link="wrist_2_link"/>
    <origin rpy="1.570796327 0 0" xyz="0 -0.08535 -1.75055776238e-11"/>
    <axis xyz="0 0 1"/>
    <limit effort="12.0" lower="-6.28318530718" upper="6.28318530718" velocity="6.28318530718"/>
    <dynamics damping="0" friction="0"/>
  </joint>
  <joint name="wrist_3_joint" type="revolute">
    <parent link="wrist_2_link"/>
    <child link="wrist_3_link"/>
    <origin rpy="1.57079632659 3.14159265359 3.14159265359" xyz="0 0.0921 -1.88900257663e-11"/>
    <axis xyz="0 0 1"/>
    <limit effort="120.0" lower="-6.28318530718" upper="6.28318530718" velocity="6.28318530718"/>
    <dynamics damping="0" friction="0"/>
  </joint>
  <!-- ROS-Industrial 'base' frame: base_link to UR 'Base' Coordinates transform -->
  <link name="base"/>
  <joint name="base_link-base_fixed_joint" type="fixed">
    <!-- Note the rotation over Z of pi radians: as base_link is REP-103
           aligned (ie: has X+ forward, Y+ left and Z+ up), this is needed
           to correctly align 'base' with the 'Base' coordinate system of
           the UR controller.
      -->
    <origin rpy="0 0 3.14159265359" xyz="0 0 0"/>
    <parent link="base_link"/>
    <child link="base"/>
  </joint>
  <!-- ROS-Industrial 'flange' frame: attachment point for EEF models -->
  <link name="flange"/>
  <joint name="wrist_3-flange" type="fixed">
    <parent link="wrist_3_link"/>
    <child link="flange"/>
    <origin rpy="0 -1.57079632679 -1.57079632679" xyz="0 0 0"/>
  </joint>
  <!-- ROS-Industrial 'tool0' frame: all-zeros tool frame -->
  <link name="tool0"/>
  <joint name="flange-tool0" type="fixed">
    <!-- default toolframe: X+ left, Y+ up, Z+ front -->
    <origin rpy="1.57079632679 0 1.57079632679" xyz="0 0 0"/>
    <parent link="flange"/>
    <child link="tool0"/>
  </joint>
  <!-- RIGHT HAND = 1, LEFT HAND = -1 -->
  <!-- BASE_LINE LINKS -->
  <joint name="right_hand_base_joint" type="fixed">
    <origin rpy="0 0 0" xyz="0 0 0"/>
    <parent link="tool0"/>
    <child link="right_hand_base_link"/>
  </joint>
  <link name="right_hand_base_link">
    <origin rpy="0 0 0" xyz="0 0 0"/>
    <visual>
      <origin rpy="0 0 0" xyz="0 0 -0.032"/>
      <geometry>
        <mesh filename="package://ur3e_description/meshes/schunk_hand/base10.dae"/>
      </geometry>
    </visual>
    <collision>
      <origin rpy="0 0 0" xyz="0 0 -0.032"/>
      <geometry>
        <mesh filename="package://ur3e_description/meshes/schunk_hand/base10.dae"/>
      </geometry>
    </collision>
  </link>
  <link name="right_hand_d">
    <!-- <visual> -->
    <!-- 	<geometry> -->
    <!-- 	  <cylinder length="0.110" radius="${cyl_radius}" /> -->
    <!-- 	</geometry> -->
    <!-- 	<material name="${name}_green" /> -->
    <!-- </visual> -->
  </link>
  <link name="right_hand_h">
    <!-- <visual> -->
    <!-- 	<origin rpy="0 1.571 0" xyz="${side*(-0.0125)} 0 0.0825" /> -->
    <!-- 	<geometry> -->
    <!-- 	  <cylinder length="0.025" radius="${cyl_radius}" /> -->
    <!-- 	</geometry> -->
    <!-- 	<material name="${name}_green" /> -->
    <!-- </visual> -->
  </link>
  <link name="right_hand_d2">
    <!-- <visual> -->
    <!-- 	<origin rpy="0 0 0" xyz="${side*(-0.025)} 0 0.09625" /> -->
    <!-- 	<geometry> -->
    <!-- 	  <cylinder length="0.0275" radius="${cyl_radius}" /> -->
    <!-- 	</geometry> -->
    <!-- 	<material name="${name}_green" /> -->
    <!-- </visual> -->
  </link>
  <!-- LENGTH NOT FOUND IN DATASHEET! GUESSED!!! -->
  <link name="right_hand_e1">
    <visual>
      <origin rpy="0 0 0" xyz="0 0.01313 0"/>
      <geometry>
        <mesh filename="package://ur3e_description/meshes/schunk_hand/h10.dae" scale="1 1 1"/>
      </geometry>
    </visual>
    <collision>
      <origin rpy="0 0 0" xyz="0 0.01313 0"/>
      <geometry>
        <mesh filename="package://ur3e_description/meshes/schunk_hand/h10.dae" scale="1 1 1"/>
      </geometry>
    </collision>
  </link>
  <!-- LENGTH NOT FOUND IN DATASHEET! GUESSED!!! -->
  <link name="right_hand_e2">
    <visual>
      <origin xyz="-0.0007 0 -0.01002"/>
      <geometry>
        <mesh filename="package://ur3e_description/meshes/schunk_hand/h11.dae" scale="1 1 1"/>
      </geometry>
    </visual>
    <collision>
      <origin xyz="-0.0007 0 -0.01002"/>
      <geometry>
        <mesh filename="package://ur3e_description/meshes/schunk_hand/h11.dae" scale="1 1 1"/>
      </geometry>
    </collision>
  </link>
  <!-- LENGTH NOT FOUND IN DATASHEET! GUESSED!!! -->
  <link name="right_hand_e3">
    <!-- <visual> -->
    <!-- 	<origin rpy="0 0 0" xyz="${side*(0.0175)} 0 0.015" /> -->
    <!-- 	<geometry> -->
    <!-- 	  <cylinder length="0.03" radius="${cyl_radius}" /> -->
    <!-- 	</geometry> -->
    <!-- 	<material name="green" /> -->
    <!-- </visual> -->
  </link>
  <link name="right_hand_e">
    </link>
  <!-- LENGTH NOT FOUND IN DATASHEET! GUESSED, BUT POSITION CALCULATED: E4 = D-G-F!!! -->
  <link name="right_hand_e4">
    <!-- <visual> -->
    <!-- 	<origin rpy="0 0 0" xyz="${side*(0.02825)} 0 0.043" /> -->
    <!-- 	<geometry> -->
    <!-- 	  <cylinder length="0.026" radius="${cyl_radius}" /> -->
    <!-- 	</geometry> -->
    <!-- 	<material name="green" /> -->
    <!-- </visual> -->
  </link>
  <!-- LENGTH NOT FOUND IN DATASHEET! GUESSED, BUT POSITION CALCULATED: E5 = D-G!!! -->
  <link name="right_hand_e5">
    <!-- <visual> -->
    <!-- 	<origin rpy="0 0 0" xyz="${side*(0.00675)} 0 0.04775" /> -->
    <!-- 	<geometry> -->
    <!-- 	  <cylinder length="0.0355" radius="${cyl_radius}" /> -->
    <!-- 	</geometry> -->
    <!-- 	<material name="green" /> -->
    <!-- </visual> -->
  </link>
  <!-- THUMB LINKS -->
  <link name="right_hand_z">
    <visual>
      <origin xyz="0 0 0.02442"/>
      <geometry>
        <mesh filename="package://ur3e_description/meshes/schunk_hand/d10.dae" scale="1 1 1"/>
      </geometry>
    </visual>
    <collision>
      <origin xyz="0 0 0.02442"/>
      <geometry>
        <mesh filename="package://ur3e_description/meshes/schunk_hand/d10.dae" scale="1 1 1"/>
      </geometry>
    </collision>
  </link>
  <link name="right_hand_virtual_a"/>
  <link name="right_hand_a">
    <visual>
      <geometry>
        <mesh filename="package://ur3e_description/meshes/schunk_hand/d11.dae" scale="1 1 1"/>
      </geometry>
    </visual>
    <collision>
      <geometry>
        <mesh filename="package://ur3e_description/meshes/schunk_hand/d11.dae" scale="1 1 1"/>
      </geometry>
    </collision>
  </link>
  <link name="right_hand_b">
    <visual>
      <geometry>
        <mesh filename="package://ur3e_description/meshes/schunk_hand/d12.dae" scale="1 1 1"/>
      </geometry>
    </visual>
    <collision>
      <geometry>
        <mesh filename="package://ur3e_description/meshes/schunk_hand/d12.dae" scale="1 1 1"/>
      </geometry>
    </collision>
  </link>
  <link name="right_hand_c">
    <visual>
      <geometry>
        <mesh filename="package://ur3e_description/meshes/schunk_hand/d13.dae" scale="1 1 1"/>
      </geometry>
    </visual>
    <collision>
      <geometry>
        <mesh filename="package://ur3e_description/meshes/schunk_hand/d13.dae" scale="1 1 1"/>
      </geometry>
    </collision>
  </link>
  <!-- INDEX FINGER LINKS -->
  <link name="right_hand_virtual_l">
    <visual>
      <origin xyz="0 0 0.01321"/>
      <geometry>
        <mesh filename="package://ur3e_description/meshes/schunk_hand/f10.dae"/>
      </geometry>
    </visual>
    <collision>
      <origin xyz="0 0 0.01321"/>
      <geometry>
        <mesh filename="package://ur3e_description/meshes/schunk_hand/f10.dae"/>
      </geometry>
    </collision>
  </link>
  <link name="right_hand_l">
    <visual>
      <geometry>
        <mesh filename="package://ur3e_description/meshes/schunk_hand/f11.dae"/>
      </geometry>
    </visual>
    <collision>
      <geometry>
        <mesh filename="package://ur3e_description/meshes/schunk_hand/f11.dae"/>
      </geometry>
    </collision>
  </link>
  <link name="right_hand_p">
    <visual>
      <geometry>
        <mesh filename="package://ur3e_description/meshes/schunk_hand/f12.dae"/>
      </geometry>
    </visual>
    <collision>
      <geometry>
        <mesh filename="package://ur3e_description/meshes/schunk_hand/f12.dae"/>
      </geometry>
    </collision>
  </link>
  <link name="right_hand_t">
    <visual>
      <geometry>
        <mesh filename="package://ur3e_description/meshes/schunk_hand/f13.dae"/>
      </geometry>
    </visual>
    <collision>
      <geometry>
        <mesh filename="package://ur3e_description/meshes/schunk_hand/f13.dae"/>
      </geometry>
    </collision>
  </link>
  <!-- MIDDLE FINGER LINKS -->
  <link name="right_hand_virtual_k">
    <visual>
      <origin xyz="0 0 0.01321"/>
      <geometry>
        <mesh filename="package://ur3e_description/meshes/schunk_hand/f20.dae"/>
      </geometry>
    </visual>
    <collision>
      <origin xyz="0 0 0.01321"/>
      <geometry>
        <mesh filename="package://ur3e_description/meshes/schunk_hand/f20.dae"/>
      </geometry>
    </collision>
  </link>
  <link name="right_hand_k">
    <visual>
      <geometry>
        <mesh filename="package://ur3e_description/meshes/schunk_hand/f21.dae"/>
      </geometry>
    </visual>
    <collision>
      <geometry>
        <mesh filename="package://ur3e_description/meshes/schunk_hand/f21.dae"/>
      </geometry>
    </collision>
  </link>
  <link name="right_hand_o">
    <visual>
      <geometry>
        <mesh filename="package://ur3e_description/meshes/schunk_hand/f22.dae"/>
      </geometry>
    </visual>
    <collision>
      <geometry>
        <mesh filename="package://ur3e_description/meshes/schunk_hand/f22.dae"/>
      </geometry>
    </collision>
  </link>
  <link name="right_hand_s">
    <visual>
      <geometry>
        <mesh filename="package://ur3e_description/meshes/schunk_hand/f23.dae"/>
      </geometry>
    </visual>
    <collision>
      <geometry>
        <mesh filename="package://ur3e_description/meshes/schunk_hand/f23.dae"/>
      </geometry>
    </collision>
  </link>
  <!-- RING FINGER LINKS -->
  <link name="right_hand_virtual_j">
    <visual>
      <origin xyz="0 0 -0.01321"/>
      <geometry>
        <mesh filename="package://ur3e_description/meshes/schunk_hand/f30.dae"/>
      </geometry>
    </visual>
    <collision>
      <origin xyz="0 0 -0.01321"/>
      <geometry>
        <mesh filename="package://ur3e_description/meshes/schunk_hand/f30.dae"/>
      </geometry>
    </collision>
  </link>
  <link name="right_hand_j">
    <visual>
      <geometry>
        <mesh filename="package://ur3e_description/meshes/schunk_hand/f31.dae"/>
      </geometry>
    </visual>
    <collision>
      <geometry>
        <mesh filename="package://ur3e_description/meshes/schunk_hand/f31.dae"/>
      </geometry>
    </collision>
  </link>
  <link name="right_hand_n">
    <visual>
      <geometry>
        <mesh filename="package://ur3e_description/meshes/schunk_hand/f32.dae"/>
      </geometry>
    </visual>
    <collision>
      <geometry>
        <mesh filename="package://ur3e_description/meshes/schunk_hand/f32.dae"/>
      </geometry>
    </collision>
  </link>
  <link name="right_hand_r">
    <visual>
      <geometry>
        <mesh filename="package://ur3e_description/meshes/schunk_hand/f33.dae"/>
      </geometry>
    </visual>
    <collision>
      <geometry>
        <mesh filename="package://ur3e_description/meshes/schunk_hand/f33.dae"/>
      </geometry>
    </collision>
  </link>
  <!-- LITTLE FINGER LINKS -->
  <link name="right_hand_virtual_i">
    <visual>
      <origin xyz="0 0 -0.01321"/>
      <geometry>
        <mesh filename="package://ur3e_description/meshes/schunk_hand/f40.dae"/>
      </geometry>
    </visual>
    <collision>
      <origin xyz="0 0 -0.01321"/>
      <geometry>
        <mesh filename="package://ur3e_description/meshes/schunk_hand/f40.dae"/>
      </geometry>
    </collision>
  </link>
  <link name="right_hand_i">
    <visual>
      <geometry>
        <mesh filename="package://ur3e_description/meshes/schunk_hand/f41.dae"/>
      </geometry>
    </visual>
    <collision>
      <geometry>
        <mesh filename="package://ur3e_description/meshes/schunk_hand/f41.dae"/>
      </geometry>
    </collision>
  </link>
  <link name="right_hand_m">
    <visual>
      <geometry>
        <mesh filename="package://ur3e_description/meshes/schunk_hand/f42.dae"/>
      </geometry>
    </visual>
    <collision>
      <geometry>
        <mesh filename="package://ur3e_description/meshes/schunk_hand/f42.dae"/>
      </geometry>
    </collision>
  </link>
  <link name="right_hand_q">
    <visual>
      <geometry>
        <mesh filename="package://ur3e_description/meshes/schunk_hand/f43.dae"/>
      </geometry>
    </visual>
    <collision>
      <geometry>
        <mesh filename="package://ur3e_description/meshes/schunk_hand/f43.dae"/>
      </geometry>
    </collision>
  </link>
  <joint name="right_hand_Thumb_Flexion" type="revolute">
    <parent link="right_hand_virtual_a"/>
    <child link="right_hand_a"/>
    <limit effort="1000.0" lower="0.0" upper="0.9704" velocity="1"/>
    <origin rpy="0 0 -0.9704" xyz="0 0 0"/>
    <axis xyz="0 0 1"/>
  </joint>
  <joint name="right_hand_Thumb_Helper" type="fixed">
    <parent link="right_hand_z"/>
    <child link="right_hand_virtual_a"/>
    <origin rpy="0 -1.5707 3.1416" xyz="0 0 0.04596"/>
  </joint>
  <!-- BASE_LINE JOINTS -->
  <joint name="right_hand_Thumb_Opposition" type="revolute">
    <parent link="right_hand_e1"/>
    <child link="right_hand_z"/>
    <limit effort="1000.0" lower="0.0" upper="0.9879" velocity="1"/>
    <origin rpy="0 0.2618 1.571" xyz="-0.0169 0.02626 0"/>
    <axis xyz="0 0 -1"/>
  </joint>
  <!-- JOINT NOT FOR BASE_LINE. BUT WRITTEN DOWN HERE FOR BETTER UX -->
  <joint name="right_hand_f1" type="fixed">
    <parent link="right_hand_e1"/>
    <child link="right_hand_d"/>
    <origin rpy="0 0 0" xyz="0 0 0"/>
  </joint>
  <joint name="right_hand_f2" type="fixed">
    <parent link="right_hand_d"/>
    <child link="right_hand_h"/>
    <origin rpy="0 0 0" xyz="0 0 0"/>
  </joint>
  <joint name="right_hand_f3" type="fixed">
    <parent link="right_hand_h"/>
    <child link="right_hand_d2"/>
    <origin rpy="0 0 0" xyz="0 0 0"/>
  </joint>
  <joint name="right_hand_f4" type="fixed">
    <parent link="right_hand_base_link"/>
    <child link="right_hand_e1"/>
    <origin rpy="0 0 0" xyz="0 -0.01313 0"/>
  </joint>
  <joint name="right_hand_j5" type="revolute">
    <parent link="right_hand_e1"/>
    <child link="right_hand_e2"/>
    <limit effort="1000.0" lower="0.0" upper="0.98786" velocity="1"/>
    <origin rpy="0 0 0" xyz="0.0184 0.006 0.0375"/>
    <axis xyz="0 0 1"/>
    <mimic joint="right_hand_Thumb_Opposition" multiplier="1" offset="0"/>
  </joint>
  <joint name="right_hand_f5" type="fixed">
    <parent link="right_hand_e2"/>
    <child link="right_hand_e3"/>
    <origin rpy="0 0 0" xyz="0 -0.0060 0"/>
  </joint>
  <joint name="right_hand_f6" type="fixed">
    <parent link="right_hand_e3"/>
    <child link="right_hand_e"/>
    <origin rpy="0 0 0" xyz="0 0 0"/>
  </joint>
  <joint name="right_hand_f7" type="fixed">
    <parent link="right_hand_e"/>
    <child link="right_hand_e4"/>
    <origin rpy="0 0 0" xyz="0 0 0"/>
  </joint>
  <joint name="right_hand_f8" type="fixed">
    <parent link="right_hand_e"/>
    <child link="right_hand_e5"/>
    <origin rpy="0 0 0" xyz="0 0 0"/>
  </joint>
  <!-- THUMB JOINTS -->
  <joint name="right_hand_j3" type="revolute">
    <parent link="right_hand_a"/>
    <child link="right_hand_b"/>
    <limit effort="1000.0" lower="0.0" upper="0.98506" velocity="1"/>
    <origin rpy="0 0 0" xyz="0.0485 0 0"/>
    <axis xyz="0 0 1"/>
    <mimic joint="right_hand_Thumb_Flexion" multiplier="1.01511" offset="0"/>
  </joint>
  <joint name="right_hand_j4" type="revolute">
    <parent link="right_hand_b"/>
    <child link="right_hand_c"/>
    <limit effort="1000.0" lower="0.0" upper="1.406" velocity="1"/>
    <origin rpy="0 0 0" xyz="0.030 0 0"/>
    <axis xyz="0 0 1"/>
    <mimic joint="right_hand_Thumb_Flexion" multiplier="1.44889" offset="0"/>
  </joint>
  <!-- INDEX FINGER JOINTS -->
  <joint name="right_hand_Index_Finger_Distal" type="revolute">
    <parent link="right_hand_l"/>
    <child link="right_hand_p"/>
    <limit effort="1000.0" lower="0" upper="1.334" velocity="1"/>
    <origin rpy="0 0 0" xyz="0.04804 0 0"/>
    <axis xyz="0 0 1"/>
  </joint>
  <joint name="right_hand_Index_Finger_Proximal" type="revolute">
    <parent link="right_hand_virtual_l"/>
    <child link="right_hand_l"/>
    <limit effort="1000.0" lower="0.0" upper="0.79849" velocity="1"/>
    <origin rpy="-1.5707 0 0" xyz="0 0 0"/>
    <axis xyz="0 0 1"/>
  </joint>
  <!-- JOINT Finger_Spread in BASE_LINE section for better UX -->
  <joint name="right_hand_j14" type="revolute">
    <parent link="right_hand_p"/>
    <child link="right_hand_t"/>
    <limit effort="1000.0" lower="0" upper="1.394" velocity="1"/>
    <origin rpy="0 0 0" xyz="0.026 0 0"/>
    <axis xyz="0 0 1"/>
    <mimic joint="right_hand_Index_Finger_Distal" multiplier="1.0450" offset="0"/>
  </joint>
  <!-- MIDDLE FINGER JOINTS -->
  <joint name="right_hand_Middle_Finger_Proximal" type="revolute">
    <parent link="right_hand_virtual_k"/>
    <child link="right_hand_k"/>
    <limit effort="1000.0" lower="0.0" upper="0.79849" velocity="1"/>
    <origin rpy="-1.5707 0 0" xyz="0 0 0"/>
    <axis xyz="0 0 1"/>
  </joint>
  <joint name="right_hand_Middle_Finger_Distal" type="revolute">
    <parent link="right_hand_k"/>
    <child link="right_hand_o"/>
    <limit effort="1000.0" lower="0" upper="1.334" velocity="1"/>
    <origin rpy="0 0 0" xyz="0.05004 0 0"/>
    <axis xyz="0 0 1"/>
  </joint>
  <joint name="right_hand_j15" type="revolute">
    <parent link="right_hand_o"/>
    <child link="right_hand_s"/>
    <limit effort="1000.0" lower="0" upper="1.334" velocity="1"/>
    <origin rpy="0 0 0" xyz="0.032 0 0"/>
    <axis xyz="0 0 1"/>
    <mimic joint="right_hand_Middle_Finger_Distal" multiplier="1.0454" offset="0"/>
  </joint>
  <!-- RING FINGER JOINTS -->
  <joint name="right_hand_Ring_Finger" type="revolute">
    <parent link="right_hand_virtual_j"/>
    <child link="right_hand_j"/>
    <limit effort="1000.0" lower="0.0" upper="0.98175" velocity="1"/>
    <origin rpy="1.5707 0 0" xyz="0 0 0"/>
    <axis xyz="0 0 1"/>
  </joint>
  <joint name="right_hand_j12" type="revolute">
    <parent link="right_hand_j"/>
    <child link="right_hand_n"/>
    <limit effort="1000.0" lower="0" upper="1.334" velocity="1"/>
    <origin rpy="0 0 0" xyz="0.05004 0 0"/>
    <axis xyz="0 0 1"/>
    <mimic joint="right_hand_Ring_Finger" multiplier="1.3588" offset="0"/>
  </joint>
  <joint name="right_hand_j16" type="revolute">
    <parent link="right_hand_n"/>
    <child link="right_hand_r"/>
    <limit effort="1000.0" lower="0" upper="1.395" velocity="1"/>
    <origin rpy="0 0 0" xyz="0.032 0 0"/>
    <axis xyz="0 0 1"/>
    <mimic joint="right_hand_Ring_Finger" multiplier="1.42093" offset="0"/>
  </joint>
  <!-- PINKY JOINTS -->
  <joint name="right_hand_Pinky" type="revolute">
    <parent link="right_hand_virtual_i"/>
    <child link="right_hand_i"/>
    <limit effort="1000.0" lower="0.0" upper="0.98175" velocity="1"/>
    <origin rpy="1.5707 0 0" xyz="0 0 0"/>
    <axis xyz="0 0 1"/>
  </joint>
  <joint name="right_hand_j13" type="revolute">
    <parent link="right_hand_i"/>
    <child link="right_hand_m"/>
    <limit effort="1000.0" lower="0" upper="1.334" velocity="1"/>
    <origin rpy="0 0 0" xyz="0.04454 0 0"/>
    <axis xyz="0 0 1"/>
    <mimic joint="right_hand_Pinky" multiplier="1.35880" offset="0"/>
  </joint>
  <joint name="right_hand_j17" type="revolute">
    <parent link="right_hand_m"/>
    <child link="right_hand_q"/>
    <limit effort="1000.0" lower="0" upper="1.3971" velocity="1"/>
    <origin rpy="0 0 0" xyz="0.022 0 0"/>
    <axis xyz="0 0 1"/>
    <mimic joint="right_hand_Pinky" multiplier="1.42307" offset="0"/>
  </joint>
  <joint name="right_hand_index_spread" type="revolute">
    <parent link="right_hand_d2"/>
    <child link="right_hand_virtual_l"/>
    <limit effort="1000.0" lower="0.0" upper="0.28833" velocity="1"/>
    <origin rpy="0 -1.5707 1.5707" xyz="-0.025 0 0.110"/>
    <axis xyz="0 0 1"/>
    <mimic joint="right_hand_Finger_Spread" multiplier="0.5" offset="0"/>
  </joint>
  <joint name="right_hand_middle_spread_dummy" type="fixed">
    <parent link="right_hand_d"/>
    <child link="right_hand_virtual_k"/>
    <origin rpy="0 -1.5707 1.5707" xyz="0 0 0.110"/>
  </joint>
  <joint name="right_hand_ring_spread" type="revolute">
    <parent link="right_hand_e5"/>
    <child link="right_hand_virtual_j"/>
    <limit effort="1000.0" lower="0.0" upper="0.28833" velocity="1"/>
    <origin rpy="-1.5707 -1.5707 0" xyz="0.003855 0 0.0655"/>
    <axis xyz="0 0 1"/>
    <mimic joint="right_hand_Finger_Spread" multiplier="0.5" offset="0"/>
  </joint>
  <joint name="right_hand_Finger_Spread" type="revolute">
    <parent link="right_hand_e4"/>
    <child link="right_hand_virtual_i"/>
    <limit effort="1000.0" lower="0.0" upper="0.5829" velocity="1"/>
    <origin rpy="-1.5707 -1.5707 0" xyz="0.025355 0 0.056"/>
    <axis xyz="0 0 1"/>
  </joint>
</robot>
