<?xml version="1.0" ?>
<!-- =================================================================================== -->
<!-- |    This document was autogenerated by xacro from robots/omnipointer_arm_only.urdf.xacro | -->
<!-- |    EDITING THIS FILE BY HAND IS NOT RECOMMENDED                                 | -->
<!-- =================================================================================== -->
<robot name="omnipointer" xmlns:xacro="http://ros.org/wiki/xacro">
  <!--MX64trntbl + MX106:  ? + 0.153 -->
  <!-- singleaxismount + 2.5girder + singleaxismount + base + MX106: 0.007370876 + 0.0226796 + 0.007370876 + ? + 0.153 -->
  <!-- frame106 + singleaxismount + adjustgirder + singleaxismount + base + MX28: 0.0907185 + 0.00737088 + 0.110563 + 0.00737088 + ? + 0.077 -->
  <!-- frame28 + singleaxismount + 5girder + singleaxismount + base + MX28: 0.0907185 + 0.00737088 + 0.0368544 + 0.00737088 + ? + 0.077 -->
  <!-- frame28 + singleaxismount + 2.5girder + singleaxismount + tip: 0.0907185 + 0.00737088 + 0.0226796 + 0.00737088 + ? -->
  <material name="omni/Blue">
    <color rgba="0 0 0.8 1"/>
  </material>
  <material name="omni/Red">
    <color rgba="1 0 0 1"/>
  </material>
  <material name="omni/Green">
    <color rgba="0 1 0 1"/>
  </material>
  <material name="omni/Yellow">
    <color rgba="1 1 0 1"/>
  </material>
  <material name="omni/LightGrey">
    <color rgba="0.6 0.6 0.6 1"/>
  </material>
  <material name="omni/DarkGrey">
    <color rgba="0.4 0.4 0.4 1"/>
  </material>
  <!-- Now we can start using the macros xacro:included above to define the actual omnipointer -->
  <!-- The first use of a macro.  This one was defined in youbot_base/base.urdf.xacro above.
       A macro like this will expand to a set of link and joint definitions, and to additional
       Gazebo-related extensions (sensor plugins, etc).  The macro takes an argument, name,
       that equals "base", and uses it to generate names for its component links and joints
       (e.g., base_link).  The xacro:included origin block is also an argument to the macro.  By convention,
       the origin block defines where the component is w.r.t its parent (in this case the parent
       is the world frame). For more, see http://www.ros.org/wiki/xacro -->
  <!-- foot for arm-->
  <!-- <link name="base_link">
    <inertial>
       <origin xyz="0 0 0" rpy="0 0 0"/>
       <mass value="10.0"/>
       <inertia ixx="0.1"  ixy="0"  ixz="0" iyy="0.1" iyz="0" izz="0.1" />
    </inertial>
  </link> -->
  <!-- joint between base_link and arm_0_link -->
  <!-- <joint name="${name}_joint_0" type="fixed" >
      <xacro:insert_block name="origin" />
      <parent link="${parent}" />
      <child link="${name}_link_0" />
    </joint> -->
  <link name="base_link">
    <visual>
      <origin rpy="0 0 0" xyz="0 0 0.05715"/>
      <geometry>
        <box size="0.1143 0.0545 0.1143"/>
      </geometry>
      <material name="omni/LightGrey"/>
    </visual>
    <collision>
      <origin rpy="0 0 0" xyz="0 0 0.05715"/>
      <geometry>
        <box size="0.1143 0.0545 0.1143"/>
      </geometry>
    </collision>
    <inertial>
      <!-- CENTER OF MASS -->
      <origin rpy="0 0 0" xyz="0 0 0.05715"/>
      <mass value="0.2"/>
      <!-- box inertia: 1/12*m(y^2+z^2), ... -->
      <inertia ixx="0.000267245666667" ixy="0" ixz="0" iyy="0.000435483" iyz="0" izz="0.000267245666667"/>
    </inertial>
  </link>
  <joint name="pendulum_joint_1" type="continuous">
    <parent link="base_link"/>
    <child link="pendulum_link_1"/>
    <limit effort="2.5" velocity="10.0"/>
    <origin rpy="0 0 0" xyz="0 0.05225 0.05715"/>
    <axis xyz="0 1 0"/>
  </joint>
  <link name="pendulum_link_1">
    <visual>
      <origin rpy="0 0 0" xyz="0 0 0.5"/>
      <geometry>
        <box size="0.0402 0.05 1"/>
      </geometry>
      <material name="omni/Blue"/>
    </visual>
    <collision>
      <origin rpy="0 0 0" xyz="0 0 0.5"/>
      <geometry>
        <box size="0.0402 0.05 1"/>
      </geometry>
    </collision>
    <inertial>
      <!-- CENTER OF MASS -->
      <origin rpy="0 0 0" xyz="0 0 0.5"/>
      <mass value="1"/>
      <!-- box inertia: 1/12*m(y^2+z^2), ... -->
      <inertia ixx="0.0835416666667" ixy="0" ixz="0" iyy="0.0834680033333" iyz="0" izz="0.000343003333333"/>
    </inertial>
  </link>
  <!-- <joint name="${name}_joint_2" type="revolute">
      <parent link="${name}_link_1"/>
      <child link="${name}_link_2"/>
      <limit effort="${joint_eff}" lower="${-joint_lim/2}" upper="${joint_lim/2}" velocity="${joint_vel}"/>
      <origin xyz="0 0 ${link_1_length}" rpy="0 0 0"/>
      <axis xyz="0 1 0"/>
    </joint>

    <xacro:box_link name="${name}_link_2" width="${link_2_width}" depth="${link_2_depth}" length="${link_2_length}" mass="${link_2_mass}" color="omni/Red"/>

    <joint name="${name}_joint_3" type="revolute">
      <parent link="${name}_link_2"/>
      <child link="${name}_link_3"/>
      <limit effort="${joint_eff}" lower="${-joint_lim/2}" upper="${joint_lim/2}" velocity="${joint_vel}"/>
      <origin xyz="0 0 ${link_2_length}" rpy="0 0 0"/>
      <axis xyz="0 1 0"/>
    </joint>

    <xacro:box_link name="${name}_link_3" width="${link_3_width}" depth="${link_3_depth}" length="${link_3_length}" mass="${link_3_mass}" color="omni/Yellow"/>

    <joint name="${name}_joint_4" type="revolute">
      <parent link="${name}_link_3"/>
      <child link="${name}_link_4"/>
      <limit effort="${joint_eff}" lower="${-joint_lim/2}" upper="${joint_lim/2}" velocity="${joint_vel}"/>
      <origin xyz="0 0 ${link_3_length}" rpy="0 0 0"/>
      <axis xyz="0 1 0"/>
    </joint>

    <xacro:box_link name="${name}_link_4" width="${link_4_width}" depth="${link_4_depth}" length="${link_4_length}" mass="${link_4_mass}" color="omni/Green"/>

    <joint name="${name}_joint_5" type="fixed">
      <parent link="${name}_link_4"/>
      <child link="${name}_link_5"/>
      <origin xyz="0 0 ${link_4_length}" rpy="0 0 0"/>
    </joint>

    <link name="${name}_link_5"/> -->
  <!-- END OF ARM LINKS/JOINTS -->
</robot>
