<?xml version="1.0"?>
<!--

  Copyright (c) 2014-2015, PAL Robotics, S.L.
  All rights reserved.

  This work is licensed under the Creative Commons Attribution-NonCommercial-NoDerivs 3.0 Unported License.
  To view a copy of this license, visit http://creativecommons.org/licenses/by-nc-nd/3.0/ or send a letter to
  Creative Commons, 444 Castro Street, Suite 900, Mountain View, California, 94041, USA.
-->
<robot xmlns:xacro="http://ros.org/wiki/xacro">

  <!--File includes-->
  <xacro:include filename="$(find tiago_description)/urdf/deg_to_rad.xacro" />
  <xacro:include filename="$(find tiago_description)/urdf/arm/wrist.urdf.xacro" />
  <xacro:include filename="$(find tiago_description)/urdf/arm/arm.transmission.xacro" />
  <xacro:include filename="$(find tiago_description_calibration)/urdf/calibration/calibration_constants.urdf.xacro" />

  <!--Constant parameters-->
  <xacro:property name="arm_friction"       value="1.0" />
  <xacro:property name="arm_damping"        value="1.0" />
  <xacro:property name="arm_1_max_vel"      value="2.7" />
  <xacro:property name="arm_2_max_vel"      value="3.66" />
  <xacro:property name="arm_3_max_vel"      value="4.58" />
  <xacro:property name="arm_4_max_vel"      value="4.58" />
  <xacro:property name="arm_1_max_effort"   value="39.0" />
  <xacro:property name="arm_2_max_effort"   value="39.0" />
  <xacro:property name="arm_3_max_effort"   value="17.86" />
  <xacro:property name="arm_4_max_effort"   value="17.86" />
  <xacro:property name="arm_eps"            value="0.07" />


  <xacro:macro name="tiago_arm" params="name parent wrist_6_range *origin">

    <!--************************-->
    <!--        SHOULDER        -->
    <!--************************-->
    <link name="${name}_1_link">
      <inertial>
        <origin xyz="0.063989 0.022546 -0.014608" rpy="0.00000 0.00000 0.00000"/>
        <mass value="2.083078"/>
        <inertia ixx="0.003003" ixy="0.002396" ixz="0.001531"
                 iyy="0.008613" iyz="0.000588"
                 izz="0.009348"/>
      </inertial>
      <!-- M90 module -->
      <visual>
        <origin xyz="0 0 0" rpy="0 0 0" />
        <geometry>
          <mesh filename="package://tiago_description/meshes/arm/arm_1.stl" scale="1 1 1"/>
        </geometry>
        <material name="White"/>
      </visual>
      <collision>
        <origin xyz="0 0 0" rpy="0 0 0" />
        <geometry>
          <mesh filename="package://tiago_description/meshes/arm/arm_1_collision.dae" scale="1 1 1"/>
        </geometry>
      </collision>
    </link>

    <joint name="${name}_1_joint" type="revolute">
      <parent link="${parent}" />
      <child link="${name}_1_link" />
      <xacro:insert_block name="origin"/>
      <axis xyz="0 0 1" />
      <limit lower="${0.0 * deg_to_rad}" upper="${157.5 * deg_to_rad}" effort="${arm_1_max_effort}" velocity="${arm_1_max_vel}" />
      <dynamics friction="${arm_friction}" damping="${arm_damping}"/>

      <safety_controller k_position="20"
                         k_velocity="20"
                         soft_lower_limit="${0.0 * deg_to_rad + arm_eps}"
                         soft_upper_limit="${157.5 * deg_to_rad - arm_eps}" />
    </joint>

   <link name="${name}_2_link">
      <inertial>
        <origin xyz="0.035264 0.000327 0.008489" rpy="0.00000 0.00000 0.00000"/>
        <mass value="1.792499"/>
        <inertia ixx="0.001683" ixy="-0.000010" ixz="-0.000387"
                 iyy="0.004708" iyz="-0.000028"
                 izz="0.004780"/>
      </inertial>
      <visual>
        <!-- <origin xyz="0 0 0" rpy="${180 * deg_to_rad} ${0 * deg_to_rad} ${-90 * deg_to_rad}" /> -->
        <origin xyz="0 0 0" rpy="${0 * deg_to_rad} ${0 * deg_to_rad} ${0 * deg_to_rad}" />
        <geometry>
          <mesh filename="package://tiago_description/meshes/arm/arm_2.stl" scale="1 1 1"/>
        </geometry>
        <material name="DarkGrey" />
      </visual>
      <collision>
        <!-- <origin xyz="0 0 0" rpy="${180 * deg_to_rad} ${0 * deg_to_rad} ${-90 * deg_to_rad}" /> -->
        <origin xyz="0 0 0" rpy="${0 * deg_to_rad} ${0 * deg_to_rad} ${0 * deg_to_rad}" />
        <geometry>
          <mesh filename="package://tiago_description/meshes/arm/arm_2_collision.dae" scale="1 1 1"/>
        </geometry>
      </collision>
    </link>

    <joint name="${name}_2_joint" type="revolute">
      <parent link="${name}_1_link" />
      <child link="${name}_2_link" />
      <origin xyz="0.125 0.0165 -0.031"
              rpy="${90.0 * deg_to_rad} 0.0 0.0"/>
      <axis xyz="0 0 1" />
      <limit lower="${-90.0 * deg_to_rad}" upper="${62.5 * deg_to_rad}" effort="${arm_2_max_effort}" velocity="${arm_2_max_vel}" />
      <dynamics friction="${arm_friction}" damping="${arm_damping}"/>

      <safety_controller k_position="20"
                         k_velocity="20"
                         soft_lower_limit="${-90.0 * deg_to_rad  + arm_eps}"
                         soft_upper_limit="${ 62.5 * deg_to_rad - arm_eps}" />
    </joint>

    <link name="${name}_3_link">
      <inertial>
        <origin xyz="-0.007956 0.005368 -0.136320" rpy="0.00000 0.00000 0.00000"/>
        <mass value="2.275860"/>
        <inertia ixx="0.018178" ixy="-0.000143" ixz="0.001379"
                 iyy="0.018552" iyz="-0.000888"
                 izz="0.002774"/>
      </inertial>
      <visual>
        <origin xyz="0 0 0" rpy="0 0 0" />
        <geometry>
          <mesh filename="package://tiago_description/meshes/arm/arm_3.stl" scale="1 1 1"/>
        </geometry>
        <material name="DarkGrey" />
      </visual>
      <collision>
        <origin xyz="0 0 0" rpy="0 0 0" />
        <geometry>
          <mesh filename="package://tiago_description/meshes/arm/arm_3_collision.dae" scale="1 1 1"/>
        </geometry>
      </collision>
    </link>

    <joint name="${name}_3_joint" type="revolute">
      <parent link="${name}_2_link" />
      <child link="${name}_3_link" />
      <origin xyz="0.0895 0.0 0.0015"
              rpy="${-90.0 * deg_to_rad} ${0.0 * deg_to_rad} ${90.0 * deg_to_rad}"/>
      <axis xyz="0 0 1" />
      <limit lower="${-202.5 * deg_to_rad}" upper="${90.0 * deg_to_rad}" effort="${arm_3_max_effort}" velocity="${arm_3_max_vel}" />
      <dynamics friction="${arm_friction}" damping="${arm_damping}"/>

      <safety_controller k_position="20"
                         k_velocity="20"
                         soft_lower_limit="${-202.5 * deg_to_rad + arm_eps}"
                         soft_upper_limit="${ 90.0 * deg_to_rad - arm_eps}" />
    </joint>

    <!--************************-->
    <!--        ELBOW           -->
    <!--************************-->
    <link name="${name}_4_link">
      <inertial>
        <origin xyz="-0.095658 0.014666 0.018133" rpy="0.00000 0.00000 0.00000"/>
        <mass value="1.892788"/>
        <inertia ixx="0.002542" ixy="-0.000956" ixz="-0.001457"
                 iyy="0.011789" iyz="0.000229"
                 izz="0.012058"/>
      </inertial>
      <visual>
        <origin xyz="0 0 0" rpy="0 0 0" />
        <geometry>
          <mesh filename="package://tiago_description/meshes/arm/arm_4.stl" scale="1 1 1"/>
        </geometry>
        <material name="DarkGrey" />
      </visual>
      <collision>
        <origin xyz="0 0 0" rpy="0 0 0" />
        <geometry>
          <mesh filename="package://tiago_description/meshes/arm/arm_4_collision.dae" scale="1 1 1"/>
        </geometry>
      </collision>
    </link>

    <joint name="${name}_4_joint" type="revolute">
      <parent link="${name}_3_link" />
      <child link="${name}_4_link" />
      <origin xyz="-0.02 -0.027 -0.222"
              rpy="${-90.0 * deg_to_rad} ${-90.0 * deg_to_rad} ${0.0 * deg_to_rad}"/>
      <axis xyz="0 0 1" />
      <limit lower="${-22.5 * deg_to_rad}" upper="${135 * deg_to_rad}" effort="${arm_4_max_effort}" velocity="${arm_4_max_vel}" />
      <dynamics friction="${arm_friction}" damping="${arm_damping}"/>

      <safety_controller k_position="20"
                         k_velocity="20"
                         soft_lower_limit="${ -22.5 * deg_to_rad + arm_eps}"
                         soft_upper_limit="${ 135 * deg_to_rad - arm_eps}" />
    </joint>

   <gazebo reference="${name}_1_link">
     <mu1>0.9</mu1>
     <mu2>0.9</mu2>
     <material>Gazebo/DarkGrey</material>
   </gazebo>
   <gazebo reference="${name}_2_link">
     <mu1>0.9</mu1>
     <mu2>0.9</mu2>
     <material>Gazebo/DarkGrey</material>
   </gazebo>
   <gazebo reference="${name}_3_link">
     <mu1>0.9</mu1>
     <mu2>0.9</mu2>
     <material>Gazebo/DarkGrey</material>
   </gazebo>
   <gazebo reference="${name}_4_link">
     <mu1>0.9</mu1>
     <mu2>0.9</mu2>
     <material>Gazebo/DarkGrey</material>
   </gazebo>

   <gazebo reference="${name}_1_joint">
      <implicitSpringDamper>1</implicitSpringDamper>
   </gazebo>
   <gazebo reference="${name}_2_joint">
      <implicitSpringDamper>1</implicitSpringDamper>
   </gazebo>
   <gazebo reference="${name}_3_joint">
      <implicitSpringDamper>1</implicitSpringDamper>
   </gazebo>
   <gazebo reference="${name}_4_joint">
      <implicitSpringDamper>1</implicitSpringDamper>
   </gazebo>


    <!--************************-->
    <!--        WRIST           -->
    <!--************************-->
   <xacro:wrist name="${name}" parent="${name}_4_link" reflect="1" wrist_6_range="${wrist_6_range}"/>

    <!--***********************-->
    <!--        TOOL           -->
    <!--***********************-->
    <link name="${name}_tool_link">
      <inertial>
        <mass value="0.1" />
        <inertia ixx="0.0" ixy="0.0" ixz="0.0" iyy="0.0" iyz="0.0" izz="0.0" />
      </inertial>
      <visual>
        <origin xyz="0.001 0 0" rpy="0 ${90.0 * deg_to_rad} 0" />
        <geometry>
          <cylinder radius="0.005" length="0.005"/>
        </geometry>
        <material name="LightGrey" />
      </visual>
      <collision>
        <origin xyz="0.001 0 0" rpy="0 ${90.0 * deg_to_rad} 0" />
        <geometry>
          <cylinder radius="0.005" length="0.005"/>
        </geometry>
      </collision>
    </link>

    <joint name="${name}_tool_joint" type="fixed">
      <parent link="${name}_7_link" />
      <child link="${name}_tool_link" />
      <origin xyz="0 0 0.046" rpy="${90.0 * deg_to_rad} ${-90.0 * deg_to_rad} ${180 * deg_to_rad}" />
    </joint>


    <!-- extensions -->
    <xacro:arm_simple_transmission name="${name}" number="1" reduction="1.0" offset_value="${arm_1_joint_offset}"/>
    <xacro:arm_simple_transmission name="${name}" number="2" reduction="1.0" offset_value="${arm_2_joint_offset}"/>
    <xacro:arm_simple_transmission name="${name}" number="3" reduction="1.0" offset_value="${arm_3_joint_offset}"/>
    <xacro:arm_simple_transmission name="${name}" number="4" reduction="1.0" offset_value="${arm_4_joint_offset}"/>
  </xacro:macro>

</robot>
